Workbook

Sheet Summary
A1: Sheets decomp_review queue: the 50 live tasks
A2: Source: tsip_prd via Metabase (db id 2), snapshot 2026-09-02 00:08 UTC. Every count below is a formula over the Tasks sheet.
A3: Legend: green = approve to generating_prompt; yellow = regenerate once; red = hold, needs an engineering fix. Blue text = hardcoded input.
A5: Headline | B5: Count | C5: What it means
A6: Live tasks in decomp_review (sheets) | B6: =COUNTA(Tasks!A2:A51) | C6: Reconciles to the 45 visible in the app.
A7: Have a task outline now | B7: =COUNTIF(Tasks!P2:P51,TRUE) | C7: Ready for a sense check and APPROVE. 37 were regenerated after the admin overrides, 6 are new arrivals.
A8: Still have no outline | B8: =COUNTIF(Tasks!P2:P51,FALSE) | C8: Outline agent ran with empty context on every attempt (about 5,380 input tokens instead of 100k-1.8M).
A9: of which workbook > 4MB | B9: =COUNTIFS(Tasks!P2:P51,FALSE,Tasks!AA2:AA51,TRUE) | C9: Every task in the queue with a >4MB workbook has failed every run. Re-running will not help; hold for an engineering fix or write the outline by hand.
A10: of which small workbook | B10: =COUNTIFS(Tasks!P2:P51,FALSE,Tasks!AA2:AA51,FALSE) | C10: Worth one more regeneration (25613ef5 failed twice; 437756ce is a brand-new arrival whose first run was empty).
A11: Recommended: APPROVE | B11: =COUNTIF(Tasks!C2:C51,"APPROVE*")
A12: Recommended: regenerate once | B12: =COUNTIF(Tasks!C2:C51,"Regenerate*")
A13: Recommended: HOLD | B13: =COUNTIF(Tasks!C2:C51,"HOLD*")
A14: Approvals that need summary bullets stripped first | B14: =COUNTIF(Tasks!C2:C51,"*Strip*") | C14: The generator emitted a tab list or change summary above the real build steps (2a63059e, 0e3f0394, fa5950c9, 95606585, d75d1c87, 5961c436).
A15: Approvals flagged too-easy risk | B15: =COUNTIF(Tasks!D2:D51,"*Too-easy risk*")+COUNTIF(Tasks!D2:D51,"*Foundational risk*") | C15: Under 350 unique formulas and mostly link pulls. Likely to come back Foundational or Intermediate from SOTA.
A16: Tasks written by decompers with >= 80% too-easy history | B16: =COUNTIF(Tasks!H2:H51,">=0.8") | C16: wangche2532, infinitearbitrage, mshuriah2702, nimisha. Not a blocker, but expect SOTA to cancel a good share.
A17: Clones | B17: =COUNTIF(Tasks!V2:V51,TRUE)
A18: Output workbook smaller than input | B18: =COUNTIF(Tasks!AB2:AB51,TRUE) | C18: 95606585 only. Worth a glance; not a blocker.
A19: Input and output workbook identical | B19: =COUNTIF(Tasks!AC2:AC51,TRUE) | C19: Never happens.
A21: Agent runs | B21: Value | C21: Note
A22: Total outline-agent runs for these 45 tasks | B22: =SUM(Tasks!AD2:AD51)
A23: Runs with empty context (< 10k input tokens) | B23: =SUM(Tasks!AE2:AE51)
A24: Empty-context share | B24: =B23/B22 | C24: Platform-wide since 08-26 the rate is 12% for files under 1MB, rising to 38% for files over 6MB.
A25: Tasks whose first run was empty and second run succeeded | B25: =COUNTIFS(Tasks!AE2:AE51,1,Tasks!AD2:AD51,2,Tasks!P2:P51,TRUE) | C25: The retry worked for these. The failure is intermittent for normal-sized files.
A27: Decomper | B27: Tasks in queue | C27: With outline | D27: Approve | E27: Avg unique formulas | F27: Too-easy prior (60d)
A28: wangche2532@gmail.com | B28: =COUNTIF(Tasks!G2:G51,A28) | C28: =COUNTIFS(Tasks!G2:G51,A28,Tasks!P2:P51,TRUE) | D28: =COUNTIFS(Tasks!G2:G51,A28,Tasks!C2:C51,"APPROVE*") | E28: =IFERROR(AVERAGEIF(Tasks!G2:G51,A28,Tasks!U2:U51),"-") | F28: 0.857
A29: apathy@uchicago.edu | B29: =COUNTIF(Tasks!G2:G51,A29) | C29: =COUNTIFS(Tasks!G2:G51,A29,Tasks!P2:P51,TRUE) | D29: =COUNTIFS(Tasks!G2:G51,A29,Tasks!C2:C51,"APPROVE*") | E29: =IFERROR(AVERAGEIF(Tasks!G2:G51,A29,Tasks!U2:U51),"-") | F29: 0.556
A30: mshuriah2702@gmail.com | B30: =COUNTIF(Tasks!G2:G51,A30) | C30: =COUNTIFS(Tasks!G2:G51,A30,Tasks!P2:P51,TRUE) | D30: =COUNTIFS(Tasks!G2:G51,A30,Tasks!C2:C51,"APPROVE*") | E30: =IFERROR(AVERAGEIF(Tasks!G2:G51,A30,Tasks!U2:U51),"-") | F30: 1
A31: alec.tseung@toptal.com | B31: =COUNTIF(Tasks!G2:G51,A31) | C31: =COUNTIFS(Tasks!G2:G51,A31,Tasks!P2:P51,TRUE) | D31: =COUNTIFS(Tasks!G2:G51,A31,Tasks!C2:C51,"APPROVE*") | E31: =IFERROR(AVERAGEIF(Tasks!G2:G51,A31,Tasks!U2:U51),"-") | F31: no data
A32: infinitearbitrage@gmail.com | B32: =COUNTIF(Tasks!G2:G51,A32) | C32: =COUNTIFS(Tasks!G2:G51,A32,Tasks!P2:P51,TRUE) | D32: =COUNTIFS(Tasks!G2:G51,A32,Tasks!C2:C51,"APPROVE*") | E32: =IFERROR(AVERAGEIF(Tasks!G2:G51,A32,Tasks!U2:U51),"-") | F32: 0.875
A33: nimisha.mekala2021@gmail.com | B33: =COUNTIF(Tasks!G2:G51,A33) | C33: =COUNTIFS(Tasks!G2:G51,A33,Tasks!P2:P51,TRUE) | D33: =COUNTIFS(Tasks!G2:G51,A33,Tasks!C2:C51,"APPROVE*") | E33: =IFERROR(AVERAGEIF(Tasks!G2:G51,A33,Tasks!U2:U51),"-") | F33: 1
A34: sophie.xiao@toptal.com | B34: =COUNTIF(Tasks!G2:G51,A34) | C34: =COUNTIFS(Tasks!G2:G51,A34,Tasks!P2:P51,TRUE) | D34: =COUNTIFS(Tasks!G2:G51,A34,Tasks!C2:C51,"APPROVE*") | E34: =IFERROR(AVERAGEIF(Tasks!G2:G51,A34,Tasks!U2:U51),"-") | F34: 0
A35: Too-easy prior = share of the decomper's SOTA-scored sheets tasks (last 60 days) bucketed Foundational or Intermediate. Hardcoded from sota_priors.md.
A37: What happened today (UTC)
A38: 21:58-23:00 ali@meridian.ai pushed the 40 leftover tasks (32 no-outline + 8 thin/truncated) back through generating_outline via ADMIN_OVERRIDE.
A39: The regeneration produced an outline for 34 of them. The 6 that still failed are the five >4MB workbooks plus 25613ef5.
A40: 22:45-00:03 7 new tasks arrived from decompers (a0b42bc7, f09e7718, fdfd6024, d75d1c87, 8f99bcd7, f3efbb17, 437756ce). All but 437756ce have outlines.
A41: 00:01 The 5 tasks parked in failed_generating_outline were overridden back to generating_outline; 3 (c4ed90cb, f925d988, 5961c436) came back with outlines by 00:08, 2 (9f656c96, 4c77fbdb) were still running.
A42: 23:24-23:26 The 133 tasks approved earlier left the queue. 14 of them failed prompt generation within 5 minutes (11% vs a 0.5-2% daily norm); release the next batch in groups of about 20.
A43: Every one of the 45 tasks sits at "generating_outline -> decomp_review (SUBMIT_TASK_OUTLINE)" as its last transition. Nobody has reviewed them; the pool is disabled for this state.

Sheet Tasks
A1: Task | B1: Diagnosis | C1: Recommended action | D1: Quality flags (from reading the outline) | E1: Evidence | F1: Bucket in 09-01 triage | G1: Decomper | H1: Decomper too-easy prior | I1: Decomper SOTA-scored (n) | J1: Entered decomp_review (UTC) | K1: Days waiting | L1: decomp_review visits | M1: Outline generations | N1: Admin overrides | O1: Override by | P1: Has outline | Q1: Outline chars (now) | R1: Outline chars (09-01 snapshot) | S1: Bullets | T1: Transition chars | U1: Unique formulas | V1: Is clone | W1: Input workbook | X1: Input KB | Y1: Output workbook | Z1: Output KB | AA1: Largest file > 4MB | AB1: Output smaller than input | AC1: Files identical | AD1: Agent runs | AE1: Empty-context runs | AF1: Last run status | AG1: Last run input tokens | AH1: Last run output tokens | AI1: Source file (decomper upload) | AJ1: Cloned from task | AK1: Task ID
A2: 7215fd35 | B2: NO OUTLINE - agent ran with empty context on every attempt | C2: HOLD. Do not re-run. Workbook is over 4MB and has failed 2 of 2 runs (5,38x input tokens = workbook never loaded). Needs an engineering fix to the outline agent, or a manual outline. | E2: 2 agent runs, 2 with empty context (last run: 5384 in / 1 out). Workbooks 4614KB in / 6416KB out. | F2: A1_no_outline | G2: alec.tseung@toptal.com | I2: 0 | J2: 46266.916 | K2: 0.1 | L2: 2 | M2: 2 | N2: 1 | O2: ali@meridian.ai | P2: FALSE | Q2: 0 | S2: 0 | T2: 226 | U2: 220747 | V2: FALSE | W2: 08.27_139_N-3.xlsx | X2: 4614 | Y2: 08.27_139_N-2.xlsx | Z2: 6417 | AA2: TRUE | AB2: FALSE | AC2: FALSE | AD2: 2 | AE2: 2 | AF2: completed | AG2: 5384 | AH2: 1 | AK2: 7215fd35-f477-44af-b6f1-b38348ebe264
A3: 3d3b229e | B3: NO OUTLINE - agent ran with empty context on every attempt | C3: HOLD. Do not re-run. Workbook is over 4MB and has failed 2 of 2 runs (5,38x input tokens = workbook never loaded). Needs an engineering fix to the outline agent, or a manual outline. | E3: 2 agent runs, 2 with empty context (last run: 5387 in / 7 out). Workbooks 4161KB in / 4446KB out. | F3: A1_no_outline | G3: alec.tseung@toptal.com | I3: 0 | J3: 46266.918 | K3: 0.1 | L3: 2 | M3: 2 | N3: 1 | O3: ali@meridian.ai | P3: FALSE | Q3: 0 | S3: 0 | T3: 42 | U3: 22547 | V3: FALSE | W3: 08.27_139_N-5.xlsx | X3: 4162 | Y3: 08.27_139_N-4.xlsx | Z3: 4446 | AA3: TRUE | AB3: FALSE | AC3: FALSE | AD3: 2 | AE3: 2 | AF3: completed | AG3: 5387 | AH3: 7 | AK3: 3d3b229e-0507-4539-8343-193a679d5f5c
A4: 337252e6 | B4: NO OUTLINE - agent ran with empty context on every attempt | C4: HOLD. Do not re-run. Workbook is over 4MB and has failed 2 of 2 runs (5,38x input tokens = workbook never loaded). Needs an engineering fix to the outline agent, or a manual outline. | E4: 2 agent runs, 2 with empty context (last run: 5387 in / 1 out). Workbooks 6416KB in / 6852KB out. | F4: A1_no_outline | G4: alec.tseung@toptal.com | I4: 0 | J4: 46266.925 | K4: 0.1 | L4: 2 | M4: 2 | N4: 1 | O4: ali@meridian.ai | P4: FALSE | Q4: 0 | S4: 0 | T4: 61 | U4: 17725 | V4: FALSE | W4: 08.27_139_N-2.xlsx | X4: 6417 | Y4: 08.27_139_N-1.xlsx | Z4: 6852 | AA4: TRUE | AB4: FALSE | AC4: FALSE | AD4: 2 | AE4: 2 | AF4: completed | AG4: 5387 | AH4: 1 | AK4: 337252e6-80dc-4b36-b284-7b83b4e5617f
A5: 8a8066ff | B5: NO OUTLINE - agent ran with empty context on every attempt | C5: HOLD. Do not re-run. Workbook is over 4MB and has failed 2 of 2 runs (5,38x input tokens = workbook never loaded). Needs an engineering fix to the outline agent, or a manual outline. | E5: 2 agent runs, 2 with empty context (last run: 5390 in / 5 out). Workbooks 4446KB in / 4614KB out. | F5: A1_no_outline | G5: alec.tseung@toptal.com | I5: 0 | J5: 46266.922 | K5: 0.1 | L5: 2 | M5: 2 | N5: 1 | O5: ali@meridian.ai | P5: FALSE | Q5: 0 | S5: 0 | T5: 152 | U5: 14594 | V5: FALSE | W5: 08.27_139_N-4.xlsx | X5: 4446 | Y5: 08.27_139_N-3.xlsx | Z5: 4614 | AA5: TRUE | AB5: FALSE | AC5: FALSE | AD5: 2 | AE5: 2 | AF5: completed | AG5: 5390 | AH5: 5 | AK5: 8a8066ff-7624-4fc5-981f-52a666b28967
A6: 906892cf | B6: NO OUTLINE - agent ran with empty context on every attempt | C6: HOLD. Do not re-run. Workbook is over 4MB and has failed 2 of 2 runs (5,38x input tokens = workbook never loaded). Needs an engineering fix to the outline agent, or a manual outline. | E6: 2 agent runs, 2 with empty context (last run: 5386 in / 4 out). Workbooks 7602KB in / 7681KB out. | F6: A1_no_outline | G6: infinitearbitrage@gmail.com | H6: 0.875 | I6: 16 | J6: 46266.918 | K6: 0.1 | L6: 2 | M6: 2 | N6: 1 | O6: ali@meridian.ai | P6: FALSE | Q6: 0 | S6: 0 | T6: 91 | U6: 1847 | V6: FALSE | W6: 08.29_117 N-5.xlsx | X6: 7602 | Y6: 08.29_117 N-4.xlsx | Z6: 7682 | AA6: TRUE | AB6: FALSE | AC6: FALSE | AD6: 2 | AE6: 2 | AF6: completed | AG6: 5386 | AH6: 4 | AK6: 906892cf-1049-4c2d-99ef-404e461c776f
A7: 25613ef5 | B7: NO OUTLINE - agent ran with empty context on every attempt | C7: Regenerate outline once more. File is small (405KB / 481KB) and has had 2 empty run(s); if it keeps failing treat like the large-file cases. | E7: 2 agent runs, 2 with empty context (last run: 5391 in / 4 out). Workbooks 405KB in / 481KB out. | F7: A1_no_outline | G7: wangche2532@gmail.com | H7: 0.857 | I7: 28 | J7: 46266.925 | K7: 0.1 | L7: 2 | M7: 2 | N7: 1 | O7: ali@meridian.ai | P7: FALSE | Q7: 0 | S7: 0 | T7: 196 | U7: 8528 | V7: FALSE | W7: 08.30_48 N-6.xlsx | X7: 406 | Y7: 08.30_48 N-5.xlsx | Z7: 481 | AA7: FALSE | AB7: FALSE | AC7: FALSE | AD7: 2 | AE7: 2 | AF7: completed | AG7: 5391 | AH7: 4 | AK7: 25613ef5-50aa-4ab2-b49a-4ea4b4dc519a
A8: 437756ce | B8: NO OUTLINE - agent ran with empty context on every attempt | C8: Regenerate outline once more. File is small (249KB / 259KB) and has had 1 empty run(s); if it keeps failing treat like the large-file cases. | E8: 1 agent runs, 1 with empty context (last run: 5391 in / 1 out). Workbooks 249KB in / 259KB out. | F8: NEW (arrived after the triage snapshot) | G8: wangche2532@gmail.com | H8: 0.857 | I8: 28 | J8: 46267.002 | K8: 0 | L8: 1 | M8: 1 | N8: 0 | P8: FALSE | Q8: 0 | S8: 0 | T8: 117 | U8: 211 | V8: FALSE | W8: 08.31_47 N-2.xlsx | X8: 250 | Y8: 08.31_47 N-1.xlsx | Z8: 260 | AA8: FALSE | AB8: FALSE | AC8: FALSE | AD8: 1 | AE8: 1 | AF8: completed | AG8: 5391 | AH8: 1 | AK8: 437756ce-b81b-403d-8a2d-be439ba78b4a
A9: a5f013b8 | B9: Regenerated today - outline now present (first run was empty context, second run healthy) | C9: APPROVE to generating_prompt. | E9: 19 bullets, 12065 chars. Last run 1,689,428 in / 19,764 out. | F9: A1_no_outline | G9: apathy@uchicago.edu | H9: 0.556 | I9: 9 | J9: 46266.923 | K9: 0.1 | L9: 2 | M9: 3 | N9: 1 | O9: ali@meridian.ai | P9: TRUE | Q9: 12065 | S9: 19 | T9: 172 | U9: 20166 | V9: FALSE | W9: 67a-N-3.xlsx | X9: 321 | Y9: 67a-N-2.xlsx | Z9: 538 | AA9: FALSE | AB9: FALSE | AC9: FALSE | AD9: 2 | AE9: 1 | AF9: completed | AG9: 1689428 | AH9: 19764 | AK9: a5f013b8-ef14-4437-bea0-630504093c40
A10: 4f56a4bf | B10: Regenerated today - outline now present (first run was empty context, second run healthy) | C10: APPROVE to generating_prompt. | E10: 13 bullets, 13635 chars. Last run 1,787,806 in / 13,833 out. | F10: A1_no_outline | G10: apathy@uchicago.edu | H10: 0.556 | I10: 9 | J10: 46266.923 | K10: 0.1 | L10: 2 | M10: 3 | N10: 1 | O10: ali@meridian.ai | P10: TRUE | Q10: 13635 | S10: 13 | T10: 206 | U10: 18080 | V10: FALSE | W10: 1b1-N-3.xlsx | X10: 2465 | Y10: 1b1-N-2.xlsx | Z10: 2704 | AA10: FALSE | AB10: FALSE | AC10: FALSE | AD10: 2 | AE10: 1 | AF10: completed | AG10: 1787806 | AH10: 13833 | AK10: 4f56a4bf-a1c1-4a5a-a04b-0002394e52c8
A11: e8ad8af9 | B11: Regenerated today - outline now present (first run was empty context, second run healthy) | C11: APPROVE to generating_prompt. | D11: Decomper prior: 88% of their SOTA-scored tasks came back too easy (n=16). | E11: 18 bullets, 10819 chars. Last run 661,231 in / 6,654 out. | F11: A1_no_outline | G11: infinitearbitrage@gmail.com | H11: 0.875 | I11: 16 | J11: 46266.916 | K11: 0.1 | L11: 2 | M11: 3 | N11: 1 | O11: ali@meridian.ai | P11: TRUE | Q11: 10819 | S11: 18 | T11: 54 | U11: 15492 | V11: FALSE | W11: 08.31_39 N-3.xlsx | X11: 37 | Y11: 08.31_39 N-2.xlsx | Z11: 273 | AA11: FALSE | AB11: FALSE | AC11: FALSE | AD11: 2 | AE11: 1 | AF11: completed | AG11: 661231 | AH11: 6654 | AK11: e8ad8af9-0dc2-4a47-915d-69799551aad9
A12: 15a0ebf7 | B12: Regenerated today - outline now present (first run was empty context, second run healthy) | C12: APPROVE to generating_prompt. | D12: Decomper prior: 100% of their SOTA-scored tasks came back too easy (n=2). | E12: 12 bullets, 6847 chars. Last run 902,266 in / 16,002 out. | F12: A1_no_outline | G12: nimisha.mekala2021@gmail.com | H12: 1 | I12: 2 | J12: 46266.919 | K12: 0.1 | L12: 2 | M12: 3 | N12: 1 | O12: ali@meridian.ai | P12: TRUE | Q12: 6847 | S12: 12 | T12: 87 | U12: 12659 | V12: FALSE | W12: MFESC_-_Model.redacted-hygiene_N-4.xlsx | X12: 1268 | Y12: MFESC_-_Model.redacted-hygiene_N-3.xlsx | Z12: 1390 | AA12: FALSE | AB12: FALSE | AC12: FALSE | AD12: 2 | AE12: 1 | AF12: completed | AG12: 902266 | AH12: 16002 | AK12: 15a0ebf7-8354-4e97-bdfd-764a03bef9ee
A13: f925d988 | B13: Regenerated twice today (failed loudly at 22:59, succeeded at 00:02) - outline now 8221 chars (was 5989) | C13: APPROVE to generating_prompt. | D13: One agent run from 22:55 is still marked running with empty context (a stuck record); the 00:02 run completed healthy and produced this outline. | E13: 17 bullets, 8221 chars. Last run 320,505 in / 10,551 out. | F13: D_thin_transition | G13: apathy@uchicago.edu | H13: 0.556 | I13: 9 | J13: 46267.004 | K13: 0 | L13: 2 | M13: 5 | N13: 2 | O13: ali@meridian.ai | P13: TRUE | Q13: 8221 | R13: 5989 | S13: 17 | T13: 12 | U13: 12113 | V13: FALSE | W13: fa9-N-4.xlsx | X13: 985 | Y13: fa9-N-3.xlsx | Z13: 1084 | AA13: FALSE | AB13: FALSE | AC13: FALSE | AD13: 3 | AE13: 1 | AF13: completed | AG13: 320505 | AH13: 10551 | AK13: f925d988-87c3-4cb0-a396-b583b2949382
A14: 21d534e3 | B14: Regenerated today - outline now present (first run was empty context, second run healthy) | C14: APPROVE to generating_prompt. | E14: 15 bullets, 11075 chars. Last run 617,199 in / 14,519 out. | F14: A1_no_outline | G14: apathy@uchicago.edu | H14: 0.556 | I14: 9 | J14: 46266.918 | K14: 0.1 | L14: 2 | M14: 3 | N14: 1 | O14: ali@meridian.ai | P14: TRUE | Q14: 11075 | S14: 15 | T14: 128 | U14: 10061 | V14: FALSE | W14: bbe-N-5.xlsx | X14: 666 | Y14: bbe-N-4.xlsx | Z14: 817 | AA14: FALSE | AB14: FALSE | AC14: FALSE | AD14: 2 | AE14: 1 | AF14: completed | AG14: 617199 | AH14: 14519 | AK14: 21d534e3-8c09-46e5-8a5d-b5c55c8522a2
A15: 552a9578 | B15: Regenerated today - outline now present (first run was empty context, second run healthy) | C15: APPROVE to generating_prompt. | D15: Decomper prior: 86% of their SOTA-scored tasks came back too easy (n=28). | E15: 23 bullets, 11303 chars. Last run 1,252,033 in / 15,059 out. | F15: A1_no_outline | G15: wangche2532@gmail.com | H15: 0.857 | I15: 28 | J15: 46266.92 | K15: 0.1 | L15: 2 | M15: 3 | N15: 1 | O15: ali@meridian.ai | P15: TRUE | Q15: 11303 | S15: 23 | T15: 181 | U15: 8568 | V15: FALSE | W15: 08.30_59 N-3.xlsx | X15: 393 | Y15: 08.30_59 N-2.xlsx | Z15: 511 | AA15: FALSE | AB15: FALSE | AC15: FALSE | AD15: 2 | AE15: 1 | AF15: completed | AG15: 1252033 | AH15: 15059 | AK15: 552a9578-aaf8-453b-8f58-e85a1ed40315
A16: a0b42bc7 | B16: New arrival - first visit, healthy agent run, outline present | C16: APPROVE to generating_prompt. | D16: Decomper prior: 86% of their SOTA-scored tasks came back too easy (n=28). | E16: 19 bullets, 7699 chars. Last run 1,245,622 in / 10,184 out. | F16: NEW (arrived after the triage snapshot) | G16: wangche2532@gmail.com | H16: 0.857 | I16: 28 | J16: 46266.948 | K16: 0.1 | L16: 1 | M16: 2 | N16: 0 | P16: TRUE | Q16: 7699 | S16: 19 | T16: 39 | U16: 8208 | V16: FALSE | W16: 08.31_78 N-3.xlsx | X16: 122 | Y16: 08.31_78 N-2.xlsx | Z16: 431 | AA16: FALSE | AB16: FALSE | AC16: FALSE | AD16: 1 | AE16: 0 | AF16: completed | AG16: 1245622 | AH16: 10184 | AK16: a0b42bc7-af28-40a5-80c2-7a103169a005
A17: 41fbe12c | B17: Regenerated twice today (failed loudly at 22:59, succeeded at 00:02) - outline now 14756 chars (was 0) | C17: APPROVE to generating_prompt. | E17: 32 bullets, 14756 chars. Last run 805,080 in / 13,754 out. | F17: A2_no_outline_looping | G17: apathy@uchicago.edu | H17: 0.556 | I17: 9 | J17: 46266.958 | K17: 0 | L17: 4 | M17: 5 | N17: 3 | O17: ali@meridian.ai, rishi@meridian.ai | P17: TRUE | Q17: 14756 | S17: 32 | T17: 156 | U17: 8187 | V17: TRUE | W17: 049-N-1.xlsx | X17: 323 | Y17: 049-N-0.xlsx | Z17: 468 | AA17: FALSE | AB17: FALSE | AC17: FALSE | AD17: 4 | AE17: 3 | AF17: completed | AG17: 805080 | AH17: 13754 | AJ17: 513b9b3f-fddb-4889-b6f2-ab71b1535791 | AK17: 41fbe12c-7c20-463d-96e8-4ae8700d1c0d
A18: 7b4c773f | B18: Regenerated today - outline now present (first run was empty context, second run healthy) | C18: APPROVE to generating_prompt. | E18: 19 bullets, 6881 chars. Last run 302,515 in / 8,875 out. | F18: A1_no_outline | G18: apathy@uchicago.edu | H18: 0.556 | I18: 9 | J18: 46266.917 | K18: 0.1 | L18: 2 | M18: 3 | N18: 1 | O18: ali@meridian.ai | P18: TRUE | Q18: 6881 | S18: 19 | T18: 33 | U18: 7637 | V18: FALSE | W18: bbe-N-3.xlsx | X18: 874 | Y18: bbe-N-2.xlsx | Z18: 927 | AA18: FALSE | AB18: FALSE | AC18: FALSE | AD18: 2 | AE18: 1 | AF18: completed | AG18: 302515 | AH18: 8875 | AK18: 7b4c773f-02c0-42cf-a37b-04b6773b86c0
A19: 62d0dff1 | B19: Regenerated today - outline now present (first run was empty context, second run healthy) | C19: APPROVE to generating_prompt. | D19: Decomper prior: 86% of their SOTA-scored tasks came back too easy (n=28). | E19: 14 bullets, 5587 chars. Last run 130,516 in / 6,365 out. | F19: A1_no_outline | G19: wangche2532@gmail.com | H19: 0.857 | I19: 28 | J19: 46266.916 | K19: 0.1 | L19: 2 | M19: 3 | N19: 1 | O19: ali@meridian.ai | P19: TRUE | Q19: 5587 | S19: 14 | T19: 45 | U19: 7131 | V19: FALSE | W19: 08.30_59 N-2.xlsx | X19: 511 | Y19: 08.30_59 N-1.xlsx | Z19: 601 | AA19: FALSE | AB19: FALSE | AC19: FALSE | AD19: 2 | AE19: 1 | AF19: completed | AG19: 130516 | AH19: 6365 | AK19: 62d0dff1-ef18-40ae-879c-f7dd0fc7a67e
A20: 443385cc | B20: Regenerated today - outline now present (first run was empty context, second run healthy) | C20: APPROVE to generating_prompt. | D20: Decomper prior: 86% of their SOTA-scored tasks came back too easy (n=28). | E20: 16 bullets, 7623 chars. Last run 246,647 in / 8,273 out. | F20: A1_no_outline | G20: wangche2532@gmail.com | H20: 0.857 | I20: 28 | J20: 46266.917 | K20: 0.1 | L20: 2 | M20: 3 | N20: 1 | O20: ali@meridian.ai | P20: TRUE | Q20: 7623 | S20: 16 | T20: 33 | U20: 5573 | V20: FALSE | W20: 08.30_59 N-4.xlsx | X20: 325 | Y20: 08.30_59 N-3.xlsx | Z20: 393 | AA20: FALSE | AB20: FALSE | AC20: FALSE | AD20: 2 | AE20: 1 | AF20: completed | AG20: 246647 | AH20: 8273 | AK20: 443385cc-42c6-486b-ac8e-fd8724d99160
A21: 69633abd | B21: Regenerated twice today (failed loudly at 22:59, succeeded at 00:02) - outline now 5529 chars (was 8361) | C21: APPROVE to generating_prompt. | D21: Last bullet is stray hardcode fragments (36/156, 164.7/158.7-1). History is churny: 4 decomp_review visits, 7 outline generations. | E21: 15 bullets, 5529 chars. Last run 284,605 in / 9,151 out. | F21: D_thin_transition | G21: apathy@uchicago.edu | H21: 0.556 | I21: 9 | J21: 46266.957 | K21: 0 | L21: 4 | M21: 7 | N21: 3 | O21: ali@meridian.ai, leo@meridian.ai, rishi@meridian.ai | P21: TRUE | Q21: 5529 | R21: 8361 | S21: 15 | T21: 16 | U21: 3137 | V21: FALSE | W21: c3b-N-3.xlsx | X21: 275 | Y21: c3b-N-2.xlsx | Z21: 329 | AA21: FALSE | AB21: FALSE | AC21: FALSE | AD21: 4 | AE21: 2 | AF21: completed | AG21: 284605 | AH21: 9151 | AK21: 69633abd-f051-404b-81ac-eff6a9593427
A22: d010dfa4 | B22: Regenerated today - outline now present (first run was empty context, second run healthy) | C22: APPROVE to generating_prompt. | D22: Decomper prior: 100% of their SOTA-scored tasks came back too easy (n=4). | E22: 19 bullets, 9371 chars. Last run 547,503 in / 11,701 out. | F22: A1_no_outline | G22: mshuriah2702@gmail.com | H22: 1 | I22: 4 | J22: 46266.923 | K22: 0.1 | L22: 2 | M22: 3 | N22: 1 | O22: ali@meridian.ai | P22: TRUE | Q22: 9371 | S22: 19 | T22: 1068 | U22: 3059 | V22: TRUE | W22: 6a9e8983 N-1.xlsx | X22: 1399 | Y22: 6a9e8983.xlsx | Z22: 1509 | AA22: FALSE | AB22: FALSE | AC22: FALSE | AD22: 2 | AE22: 1 | AF22: completed | AG22: 547503 | AH22: 11701 | AJ22: 218a5a0c-0db0-42ac-83bf-a147c71a322f | AK22: d010dfa4-e4d0-42a5-a7f6-a3ef1e58e0e9
A23: c4ed90cb | B23: Regenerated twice today (failed loudly at 22:59, succeeded at 00:02) - outline now 6005 chars (was 46) | C23: APPROVE to generating_prompt. | E23: 18 bullets, 6005 chars. Last run 177,709 in / 7,916 out. | F23: B_thin_outline | G23: apathy@uchicago.edu | H23: 0.556 | I23: 9 | J23: 46267.004 | K23: 0 | L23: 2 | M23: 5 | N23: 2 | O23: ali@meridian.ai | P23: TRUE | Q23: 6005 | R23: 46 | S23: 18 | T23: 44 | U23: 2828 | V23: FALSE | W23: bbe-N-4.xlsx | X23: 817 | Y23: bbe-N-3.xlsx | Z23: 874 | AA23: FALSE | AB23: FALSE | AC23: FALSE | AD23: 3 | AE23: 1 | AF23: completed | AG23: 177709 | AH23: 7916 | AK23: c4ed90cb-4e82-408b-82fa-f52a782f72d3
A24: cfb56338 | B24: Regenerated today - outline now present (first run was empty context, second run healthy) | C24: APPROVE to generating_prompt. | D24: Decomper prior: 100% of their SOTA-scored tasks came back too easy (n=4). | E24: 9 bullets, 5506 chars. Last run 468,970 in / 11,380 out. | F24: A1_no_outline | G24: mshuriah2702@gmail.com | H24: 1 | I24: 4 | J24: 46266.919 | K24: 0.1 | L24: 2 | M24: 3 | N24: 1 | O24: ali@meridian.ai | P24: TRUE | Q24: 5506 | S24: 9 | T24: 220 | U24: 2606 | V24: FALSE | W24: 6a9e8983 N-3.xlsx | X24: 1331 | Y24: 6a9e8983 N-2.xlsx | Z24: 1372 | AA24: FALSE | AB24: FALSE | AC24: FALSE | AD24: 2 | AE24: 1 | AF24: completed | AG24: 468970 | AH24: 11380 | AK24: cfb56338-4a27-42d5-9e0d-9e59b2fa8640
A25: 1998a617 | B25: Regenerated today - outline now present (first run was empty context, second run healthy) | C25: APPROVE to generating_prompt. | D25: Decomper prior: 100% of their SOTA-scored tasks came back too easy (n=2). | E25: 17 bullets, 8355 chars. Last run 590,320 in / 10,687 out. | F25: A1_no_outline | G25: nimisha.mekala2021@gmail.com | H25: 1 | I25: 2 | J25: 46266.918 | K25: 0.1 | L25: 2 | M25: 3 | N25: 1 | O25: ali@meridian.ai | P25: TRUE | Q25: 8355 | S25: 17 | T25: 255 | U25: 1856 | V25: FALSE | W25: Fremont_ASCs_Merger_Model_v7.redacted-hygiene_N-4.xlsx | X25: 606 | Y25: Fremont_ASCs_Merger_Model_v7.redacted-hygiene_N-3.xlsx | Z25: 658 | AA25: FALSE | AB25: FALSE | AC25: FALSE | AD25: 2 | AE25: 1 | AF25: completed | AG25: 590320 | AH25: 10687 | AK25: 1998a617-9037-46d2-912b-adfdb4441444
A26: 5da033e5 | B26: Regenerated today - outline now present (first run was empty context, second run healthy) | C26: APPROVE to generating_prompt. | D26: Decomper prior: 86% of their SOTA-scored tasks came back too easy (n=28). | E26: 9 bullets, 4421 chars. Last run 228,189 in / 4,614 out. | F26: A1_no_outline | G26: wangche2532@gmail.com | H26: 0.857 | I26: 28 | J26: 46266.916 | K26: 0.1 | L26: 2 | M26: 3 | N26: 1 | O26: ali@meridian.ai | P26: TRUE | Q26: 4421 | S26: 9 | T26: 151 | U26: 1645 | V26: FALSE | W26: 08.30_40 N-4.xlsx | X26: 188 | Y26: 08.30_40 N-3.xlsx | Z26: 231 | AA26: FALSE | AB26: FALSE | AC26: FALSE | AD26: 2 | AE26: 1 | AF26: completed | AG26: 228189 | AH26: 4614 | AK26: 5da033e5-0b26-4526-afaf-8e71e57612a4
A27: 27b833b2 | B27: Regenerated today - outline now present (first run was empty context, second run healthy) | C27: APPROVE to generating_prompt. | D27: Decomper prior: 100% of their SOTA-scored tasks came back too easy (n=4). | E27: 22 bullets, 6379 chars. Last run 364,933 in / 10,263 out. | F27: A1_no_outline | G27: mshuriah2702@gmail.com | H27: 1 | I27: 4 | J27: 46266.918 | K27: 0.1 | L27: 2 | M27: 3 | N27: 1 | O27: ali@meridian.ai | P27: TRUE | Q27: 6379 | S27: 22 | T27: 286 | U27: 1645 | V27: FALSE | W27: 6a9e8983 N-2.xlsx | X27: 1372 | Y27: 6a9e8983 N-1.xlsx | Z27: 1399 | AA27: FALSE | AB27: FALSE | AC27: FALSE | AD27: 2 | AE27: 1 | AF27: completed | AG27: 364933 | AH27: 10263 | AK27: 27b833b2-b759-439b-aa91-db78616e22b8
A28: c4ba7c97 | B28: Regenerated today - outline now present (first run was empty context, second run healthy) | C28: APPROVE to generating_prompt. | D28: Decomper prior: 86% of their SOTA-scored tasks came back too easy (n=28). | E28: 11 bullets, 6347 chars. Last run 186,191 in / 7,049 out. | F28: A1_no_outline | G28: wangche2532@gmail.com | H28: 0.857 | I28: 28 | J28: 46266.916 | K28: 0.1 | L28: 2 | M28: 3 | N28: 1 | O28: ali@meridian.ai | P28: TRUE | Q28: 6347 | S28: 11 | T28: 56 | U28: 1635 | V28: TRUE | W28: 08.30_24 N-1.xlsx | X28: 263 | Y28: 08.30_24 N.xlsx | Z28: 282 | AA28: FALSE | AB28: FALSE | AC28: FALSE | AD28: 2 | AE28: 1 | AF28: completed | AG28: 186191 | AH28: 7049 | AJ28: 6fe4dc2b-58b3-490f-a9fe-d87c28bf0273 | AK28: c4ba7c97-5f2e-4e3e-8f63-3d68539868bc
A29: 92b20cff | B29: Regenerated today - outline now present (first run was empty context, second run healthy) | C29: APPROVE to generating_prompt. | D29: Decomper prior: 88% of their SOTA-scored tasks came back too easy (n=16). | E29: 22 bullets, 9093 chars. Last run 488,250 in / 11,776 out. | F29: A1_no_outline | G29: infinitearbitrage@gmail.com | H29: 0.875 | I29: 16 | J29: 46266.917 | K29: 0.1 | L29: 2 | M29: 3 | N29: 1 | O29: ali@meridian.ai | P29: TRUE | Q29: 9093 | S29: 22 | T29: 84 | U29: 1598 | V29: TRUE | W29: 08.29_28 N-1.xlsx | X29: 274 | Y29: 08.29_28.xlsx | Z29: 320 | AA29: FALSE | AB29: FALSE | AC29: FALSE | AD29: 2 | AE29: 1 | AF29: completed | AG29: 488250 | AH29: 11776 | AJ29: 54b24e89-72a3-4a17-aacf-2160406784d8 | AK29: 92b20cff-2188-474c-b966-e33ada1437ee
A30: 5961c436 | B30: Regenerated twice today (failed loudly at 22:59, succeeded at 00:02) - outline now 10121 chars (was 892) | C30: APPROVE to generating_prompt. Strip the summary/meta bullets first. | D30: 4 summary bullets at the top (tab list, per-tab change notes) before the build steps; strip them. One bullet lists 46 hardcoded monthly seed values verbatim; harmless but long. Decomper prior: 86% of their SOTA-scored tasks came back too easy (n=28). | E30: 13 bullets, 10121 chars. Last run 382,469 in / 10,257 out. | F30: B_thin_outline | G30: wangche2532@gmail.com | H30: 0.857 | I30: 28 | J30: 46267.006 | K30: 0 | L30: 2 | M30: 5 | N30: 2 | O30: ali@meridian.ai | P30: TRUE | Q30: 10121 | R30: 892 | S30: 13 | T30: 195 | U30: 1330 | V30: TRUE | W30: 08.30_21 N-1.xlsx | X30: 1397 | Y30: 08.30_21 N.xlsx | Z30: 1446 | AA30: FALSE | AB30: FALSE | AC30: FALSE | AD30: 3 | AE30: 1 | AF30: completed | AG30: 382469 | AH30: 10257 | AJ30: 33471211-ec23-4812-aea8-b2f3c7fba27d | AK30: 5961c436-e583-4000-ad25-cc8e11a634ae
A31: 0e3f0394 | B31: Regenerated today - outline now present (first run was empty context, second run healthy) | C31: APPROVE to generating_prompt. Strip the summary/meta bullets first. | D31: 5 summary bullets at the top (per-tab change notes) before the build steps; strip them. | E31: 16 bullets, 9135 chars. Last run 231,844 in / 8,360 out. | F31: A1_no_outline | G31: sophie.xiao@toptal.com | H31: 0 | I31: 8 | J31: 46266.917 | K31: 0.1 | L31: 2 | M31: 3 | N31: 1 | O31: ali@meridian.ai | P31: TRUE | Q31: 9135 | S31: 16 | T31: 80 | U31: 1221 | V31: FALSE | W31: 08.31_50 N-3.xlsx | X31: 430 | Y31: 08.31_50 N-2 new.xlsx | Z31: 451 | AA31: FALSE | AB31: FALSE | AC31: FALSE | AD31: 2 | AE31: 1 | AF31: completed | AG31: 231844 | AH31: 8360 | AK31: 0e3f0394-b3e2-4e6c-836e-704eff6c48e2
A32: f3efbb17 | B32: New arrival - first visit, healthy agent run, outline present | C32: APPROVE to generating_prompt. | D32: Decomper prior: 86% of their SOTA-scored tasks came back too easy (n=28). | E32: 12 bullets, 9869 chars. Last run 144,623 in / 8,132 out. | F32: NEW (arrived after the triage snapshot) | G32: wangche2532@gmail.com | H32: 0.857 | I32: 28 | J32: 46266.999 | K32: 0 | L32: 1 | M32: 2 | N32: 0 | P32: TRUE | Q32: 9869 | S32: 12 | T32: 331 | U32: 1206 | V32: TRUE | W32: 08.31_47 N-1.xlsx | X32: 260 | Y32: 08.31_47 N.xlsx | Z32: 307 | AA32: FALSE | AB32: FALSE | AC32: FALSE | AD32: 1 | AE32: 0 | AF32: completed | AG32: 144623 | AH32: 8132 | AJ32: 2e65b7ae-9888-4bf7-99e7-ee2f3541c122 | AK32: f3efbb17-561b-44a2-8f87-28e2abf47f9f
A33: fa5950c9 | B33: Regenerated twice today (failed loudly at 22:59, succeeded at 00:02) - outline now 7081 chars (was 517) | C33: APPROVE to generating_prompt. Strip the summary/meta bullets first. | D33: 6 summary bullets at the top (tab list tagged "(heavy)") before the build steps; strip them. Decomper prior: 86% of their SOTA-scored tasks came back too easy (n=28). | E33: 15 bullets, 7081 chars. Last run 314,331 in / 8,762 out. | F33: B_thin_outline | G33: wangche2532@gmail.com | H33: 0.857 | I33: 28 | J33: 46266.958 | K33: 0 | L33: 2 | M33: 4 | N33: 1 | O33: ali@meridian.ai | P33: TRUE | Q33: 7081 | R33: 517 | S33: 15 | T33: 154 | U33: 1106 | V33: TRUE | W33: 08.30_37 N-1.xlsx | X33: 565 | Y33: 08.30_37 N.xlsx | Z33: 585 | AA33: FALSE | AB33: FALSE | AC33: FALSE | AD33: 2 | AE33: 1 | AF33: completed | AG33: 314331 | AH33: 8762 | AJ33: e2ee0dfe-ea7c-4a12-9941-7407a0e86152 | AK33: fa5950c9-4c71-4406-83bf-8fd81fc6ff67
A34: 79036bd8 | B34: Regenerated twice today (failed loudly at 22:59, succeeded at 00:02) - outline now 8908 chars (was 5975) | C34: APPROVE to generating_prompt. | E34: 14 bullets, 8908 chars. Last run 172,748 in / 7,165 out. | F34: C_truncated_outline | G34: alec.tseung@toptal.com | I34: 0 | J34: 46266.957 | K34: 0 | L34: 2 | M34: 4 | N34: 1 | O34: ali@meridian.ai | P34: TRUE | Q34: 8908 | R34: 5975 | S34: 14 | T34: 52 | U34: 1061 | V34: FALSE | W34: 08.27_141_N-2.xlsx | X34: 32 | Y34: 08.27_141_N-1.xlsx | Z34: 48 | AA34: FALSE | AB34: FALSE | AC34: FALSE | AD34: 2 | AE34: 1 | AF34: completed | AG34: 172748 | AH34: 7165 | AK34: 79036bd8-09a6-44ef-a84d-8985ace5476e
A35: 2a63059e | B35: Regenerated today - outline now present (first run was empty context, second run healthy) | C35: APPROVE to generating_prompt. Strip the summary/meta bullets first. | D35: 2 summary bullets at the top (tab list, hardcode list) before the build steps; strip them. Decomper prior: 86% of their SOTA-scored tasks came back too easy (n=28). | E35: 16 bullets, 5820 chars. Last run 201,784 in / 7,610 out. | F35: A1_no_outline | G35: wangche2532@gmail.com | H35: 0.857 | I35: 28 | J35: 46266.916 | K35: 0.1 | L35: 2 | M35: 3 | N35: 1 | O35: ali@meridian.ai | P35: TRUE | Q35: 5820 | S35: 16 | T35: 57 | U35: 1009 | V35: FALSE | W35: 08.31_63 N-4.xlsx | X35: 415 | Y35: 08.31_63 N-3.xlsx | Z35: 450 | AA35: FALSE | AB35: FALSE | AC35: FALSE | AD35: 2 | AE35: 1 | AF35: completed | AG35: 201784 | AH35: 7610 | AK35: 2a63059e-b08b-495f-90df-23bb38eccd3f
A36: 8c19520c | B36: Regenerated today - outline now present (first run was empty context, second run healthy) | C36: APPROVE to generating_prompt. | D36: Decomper prior: 86% of their SOTA-scored tasks came back too easy (n=28). | E36: 14 bullets, 5089 chars. Last run 523,608 in / 11,560 out. | F36: A1_no_outline | G36: wangche2532@gmail.com | H36: 0.857 | I36: 28 | J36: 46266.92 | K36: 0.1 | L36: 2 | M36: 3 | N36: 1 | O36: ali@meridian.ai | P36: TRUE | Q36: 5089 | S36: 14 | T36: 302 | U36: 950 | V36: FALSE | W36: 08.30_21 N-4.xlsx | X36: 996 | Y36: 08.30_21 N-3.xlsx | Z36: 1310 | AA36: FALSE | AB36: FALSE | AC36: FALSE | AD36: 2 | AE36: 1 | AF36: completed | AG36: 523608 | AH36: 11560 | AK36: 8c19520c-b2d2-449b-a1f8-b426e81df053
A37: 95606585 | B37: Regenerated twice today (failed loudly at 22:59, succeeded at 00:02) - outline now 7449 chars (was 7398) | C37: APPROVE to generating_prompt. Strip the summary/meta bullets first. | D37: 2 meta bullets at the top ("input_workbook_url = earlier = less built"); strip them. Output workbook is smaller than input (395KB vs 440KB), unusual for a forward build. Decomper prior: 86% of their SOTA-scored tasks came back too easy (n=28). | E37: 15 bullets, 7449 chars. Last run 395,365 in / 10,629 out. | F37: C_truncated_outline | G37: wangche2532@gmail.com | H37: 0.857 | I37: 28 | J37: 46266.958 | K37: 0 | L37: 2 | M37: 4 | N37: 1 | O37: ali@meridian.ai | P37: TRUE | Q37: 7449 | R37: 7398 | S37: 15 | T37: 123 | U37: 800 | V37: FALSE | W37: 08.31_44 N-4.xlsx | X37: 441 | Y37: 08.31_44 N-3.xlsx | Z37: 396 | AA37: FALSE | AB37: TRUE | AC37: FALSE | AD37: 2 | AE37: 1 | AF37: completed | AG37: 395365 | AH37: 10629 | AK37: 95606585-8665-475b-ac9c-eb5fae04a8f6
A38: 1ef09f14 | B38: Regenerated today - outline now present (first run was empty context, second run healthy) | C38: APPROVE to generating_prompt. | E38: 19 bullets, 7866 chars. Last run 80,859 in / 5,771 out. | F38: A1_no_outline | G38: sophie.xiao@toptal.com | H38: 0 | I38: 8 | J38: 46266.916 | K38: 0.1 | L38: 2 | M38: 3 | N38: 1 | O38: ali@meridian.ai | P38: TRUE | Q38: 7866 | S38: 19 | T38: 51 | U38: 681 | V38: FALSE | W38: 08.31_50 N-1.xlsx | X38: 451 | Y38: 08.31_50.xlsx | Z38: 932 | AA38: FALSE | AB38: FALSE | AC38: FALSE | AD38: 2 | AE38: 1 | AF38: completed | AG38: 80859 | AH38: 5771 | AK38: 1ef09f14-3119-434f-b561-884e196c6caa
A39: 40827f51 | B39: Regenerated twice today (failed loudly at 22:59, succeeded at 00:02) - outline now 9279 chars (was 2052) | C39: APPROVE to generating_prompt. | E39: 14 bullets, 9279 chars. Last run 111,708 in / 5,540 out. | F39: B_thin_outline | G39: apathy@uchicago.edu | H39: 0.556 | I39: 9 | J39: 46266.957 | K39: 0 | L39: 2 | M39: 4 | N39: 1 | O39: ali@meridian.ai | P39: TRUE | Q39: 9279 | R39: 2052 | S39: 14 | T39: 15 | U39: 661 | V39: FALSE | W39: 08.31_21-N-2.xlsx | X39: 27 | Y39: 08.31_21-N-1.xlsx | Z39: 45 | AA39: FALSE | AB39: FALSE | AC39: FALSE | AD39: 2 | AE39: 1 | AF39: completed | AG39: 111708 | AH39: 5540 | AK39: 40827f51-9058-4a34-aa53-cffedf1af118
A40: 8f99bcd7 | B40: New arrival - first visit, healthy agent run, outline present | C40: APPROVE to generating_prompt. | D40: Decomper prior: 100% of their SOTA-scored tasks came back too easy (n=4). | E40: 16 bullets, 6592 chars. Last run 152,153 in / 5,778 out. | F40: NEW (arrived after the triage snapshot) | G40: mshuriah2702@gmail.com | H40: 1 | I40: 4 | J40: 46266.973 | K40: 0 | L40: 1 | M40: 2 | N40: 0 | P40: TRUE | Q40: 6592 | S40: 16 | T40: 21 | U40: 638 | V40: FALSE | W40: 08.31_116 N-7.xlsx | X40: 766 | Y40: 08.31_116 N-6.xlsx | Z40: 805 | AA40: FALSE | AB40: FALSE | AC40: FALSE | AD40: 1 | AE40: 0 | AF40: completed | AG40: 152153 | AH40: 5778 | AK40: 8f99bcd7-fca6-4752-bf71-04ad795bf50d
...

Sheet No-outline detail
A1: Task | B1: Decomper | C1: Input workbook | D1: Input KB | E1: Output workbook | F1: Output KB | G1: Largest > 4MB | H1: Unique formulas | I1: Agent runs | J1: Empty-context runs | K1: Run times (UTC) and tokens in/out | L1: Transition description (what the decomper removed) | M1: Recommended action | N1: Task ID
A2: 7215fd35 | B2: alec.tseung@toptal.com | C2: 08.27_139_N-3.xlsx | D2: 4614 | E2: 08.27_139_N-2.xlsx | F2: 6417 | G2: TRUE | H2: 220747 | I2: 2 | J2: 2 | K2: 2026-09-01T18:22 completed 5392/1 | 2026-09-01T21:57 completed 5384/1 | L2: Cleared formulae across Provider Summary, P&L Summary, QE2 Provider by Modality, QE5b Provider Comp, Industry Benchmark Source, Management Fee, Physician Detail, CSC Vol & Fin Inputs, BCSC Vol & Fin Inputs, and IT Amounts tabs | M2: HOLD. Do not re-run. Workbook is over 4MB and has failed 2 of 2 runs (5,38x input tokens = workbook never loaded). Needs an engineering fix to the outline agent, or a manual outline. | N2: 7215fd35-f477-44af-b6f1-b38348ebe264
A3: 3d3b229e | B3: alec.tseung@toptal.com | C3: 08.27_139_N-5.xlsx | D3: 4162 | E3: 08.27_139_N-4.xlsx | F3: 4446 | G3: TRUE | H3: 22547 | I3: 2 | J3: 2 | K3: 2026-09-01T18:32 completed 5391/4 | 2026-09-01T21:57 completed 5387/7 | L3: Cleared remaining formulae in the workbook | M3: HOLD. Do not re-run. Workbook is over 4MB and has failed 2 of 2 runs (5,38x input tokens = workbook never loaded). Needs an engineering fix to the outline agent, or a manual outline. | N3: 3d3b229e-0507-4539-8343-193a679d5f5c
A4: 337252e6 | B4: alec.tseung@toptal.com | C4: 08.27_139_N-2.xlsx | D4: 6417 | E4: 08.27_139_N-1.xlsx | F4: 6852 | G4: TRUE | H4: 17725 | I4: 2 | J4: 2 | K4: 2026-09-01T18:17 completed 5389/4 | 2026-09-01T21:57 completed 5387/1 | L4: Cleared formulae across the key calculation tabs of the model | M4: HOLD. Do not re-run. Workbook is over 4MB and has failed 2 of 2 runs (5,38x input tokens = workbook never loaded). Needs an engineering fix to the outline agent, or a manual outline. | N4: 337252e6-80dc-4b36-b284-7b83b4e5617f
A5: 8a8066ff | B5: alec.tseung@toptal.com | C5: 08.27_139_N-4.xlsx | D5: 4446 | E5: 08.27_139_N-3.xlsx | F5: 4614 | G5: TRUE | H5: 14594 | I5: 2 | J5: 2 | K5: 2026-09-01T18:27 completed 5390/1 | 2026-09-01T21:57 completed 5390/5 | L5: Cleared formulae mainly across Fin Stage, Monthly TB - Entity, Adjustments Base Case/Valuation, Integrated Valuation, INT|MSO, 6. Int – MSO, 8. R&M tabs | M5: HOLD. Do not re-run. Workbook is over 4MB and has failed 2 of 2 runs (5,38x input tokens = workbook never loaded). Needs an engineering fix to the outline agent, or a manual outline. | N5: 8a8066ff-7624-4fc5-981f-52a666b28967
A6: 906892cf | B6: infinitearbitrage@gmail.com | C6: 08.29_117 N-5.xlsx | D6: 7602 | E6: 08.29_117 N-4.xlsx | F6: 7682 | G6: TRUE | H6: 1847 | I6: 2 | J6: 2 | K6: 2026-09-01T10:24 completed 5385/1 | 2026-09-01T21:57 completed 5386/4 | L6: maintenance analysis tab entirely and bandwidth tab and ratio tab with its dependent cells | M6: HOLD. Do not re-run. Workbook is over 4MB and has failed 2 of 2 runs (5,38x input tokens = workbook never loaded). Needs an engineering fix to the outline agent, or a manual outline. | N6: 906892cf-1049-4c2d-99ef-404e461c776f
A7: 25613ef5 | B7: wangche2532@gmail.com | C7: 08.30_48 N-6.xlsx | D7: 406 | E7: 08.30_48 N-5.xlsx | F7: 481 | G7: FALSE | H7: 8528 | I7: 2 | J7: 2 | K7: 2026-09-01T13:25 completed 5389/1 | 2026-09-01T21:57 completed 5391/4 | L7: Delete tabs: INT - Incr Vol Build, Deprec. Calc, Calculator, Summary Output, 4. Profile Clear content: 'INT - P&L'!A18:BF281, 'INT - Val & Returns'!A3:PK113, Amortization!A15:CE236, Inputs!A2:AE54 | M7: Regenerate outline once more. File is small (405KB / 481KB) and has had 2 empty run(s); if it keeps failing treat like the large-file cases. | N7: 25613ef5-50aa-4ab2-b49a-4ea4b4dc519a
A8: 437756ce | B8: wangche2532@gmail.com | C8: 08.31_47 N-2.xlsx | D8: 250 | E8: 08.31_47 N-1.xlsx | F8: 260 | G8: FALSE | H8: 211 | I8: 1 | J8: 1 | K8: 2026-09-02T00:01 completed 5391/1 | L8: Delete tabs: Northstar Partners Cash Flow & Clear content: Inputs & Assumptions!F74:K78, Inputs & Assumptions!D80:K99 | M8: Regenerate outline once more. File is small (249KB / 259KB) and has had 1 empty run(s); if it keeps failing treat like the large-file cases. | N8: 437756ce-b81b-403d-8a2d-be439ba78b4a
A10: Why "empty context": a healthy outline run reads the two workbooks and shows 60k-1.8M input tokens. These runs show ~5,384 input tokens and 1-7 output tokens: the prompt scaffolding with no workbook attached. The agent still reports status=completed, the python step strips the non-bullet output to nothing, and the backfill writes an empty task_outline.
A11: Size evidence (all sheets tasks since 08-26, from Metabase): empty-run share is 12% under 1MB, 24% at 1-2MB, 30% at 2-4MB, 32% at 4-6MB, 38% over 6MB. In this queue every >4MB task failed both attempts.

Sheet Outlines
A1: Task | B1: Recommended action | C1: Decomper | D1: Unique formulas | E1: Outline chars | F1: Transition description | G1: Task outline (as stored) | H1: Task ID
A2: 7215fd35 | B2: HOLD. Do not re-run. Workbook is over 4MB and has failed 2 of 2 runs (5,38x input tokens = workbook never loaded). Needs an engineering fix to the outline agent, or a manual outline. | C2: alec.tseung@toptal.com | D2: 220747 | E2: 0 | F2: Cleared formulae across Provider Summary, P&L Summary, QE2 Provider by Modality, QE5b Provider Comp, Industry Benchmark Source, Management Fee, Physician Detail, CSC Vol & Fin Inputs, BCSC Vol & Fin Inputs, and IT Amounts tabs | H2: 7215fd35-f477-44af-b6f1-b38348ebe264
A3: 3d3b229e | B3: HOLD. Do not re-run. Workbook is over 4MB and has failed 2 of 2 runs (5,38x input tokens = workbook never loaded). Needs an engineering fix to the outline agent, or a manual outline. | C3: alec.tseung@toptal.com | D3: 22547 | E3: 0 | F3: Cleared remaining formulae in the workbook | H3: 3d3b229e-0507-4539-8343-193a679d5f5c
A4: 337252e6 | B4: HOLD. Do not re-run. Workbook is over 4MB and has failed 2 of 2 runs (5,38x input tokens = workbook never loaded). Needs an engineering fix to the outline agent, or a manual outline. | C4: alec.tseung@toptal.com | D4: 17725 | E4: 0 | F4: Cleared formulae across the key calculation tabs of the model | H4: 337252e6-80dc-4b36-b284-7b83b4e5617f
A5: 8a8066ff | B5: HOLD. Do not re-run. Workbook is over 4MB and has failed 2 of 2 runs (5,38x input tokens = workbook never loaded). Needs an engineering fix to the outline agent, or a manual outline. | C5: alec.tseung@toptal.com | D5: 14594 | E5: 0 | F5: Cleared formulae mainly across Fin Stage, Monthly TB - Entity, Adjustments Base Case/Valuation, Integrated Valuation, INT|MSO, 6. Int – MSO, 8. R&M tabs | H5: 8a8066ff-7624-4fc5-981f-52a666b28967
A6: 906892cf | B6: HOLD. Do not re-run. Workbook is over 4MB and has failed 2 of 2 runs (5,38x input tokens = workbook never loaded). Needs an engineering fix to the outline agent, or a manual outline. | C6: infinitearbitrage@gmail.com | D6: 1847 | E6: 0 | F6: maintenance analysis tab entirely and bandwidth tab and ratio tab with its dependent cells | H6: 906892cf-1049-4c2d-99ef-404e461c776f
A7: 25613ef5 | B7: Regenerate outline once more. File is small (405KB / 481KB) and has had 2 empty run(s); if it keeps failing treat like the large-file cases. | C7: wangche2532@gmail.com | D7: 8528 | E7: 0 | F7: Delete tabs: INT - Incr Vol Build, Deprec. Calc, Calculator, Summary Output, 4. Profile Clear content: 'INT - P&L'!A18:BF281, 'INT - Val & Returns'!A3:PK113, Amortization!A15:CE236, Inputs!A2:AE54 | H7: 25613ef5-50aa-4ab2-b49a-4ea4b4dc519a
A8: 437756ce | B8: Regenerate outline once more. File is small (249KB / 259KB) and has had 1 empty run(s); if it keeps failing treat like the large-file cases. | C8: wangche2532@gmail.com | D8: 211 | E8: 0 | F8: Delete tabs: Northstar Partners Cash Flow & Clear content: Inputs & Assumptions!F74:K78, Inputs & Assumptions!D80:K99 | H8: 437756ce-b81b-403d-8a2d-be439ba78b4a
A9: a5f013b8 | B9: APPROVE to generating_prompt. | C9: apathy@uchicago.edu | D9: 20166 | E9: 12065 | F9: Cleared Pro Forma, D&A & Debt Schedules, DCF & IRR, Intangible Asset Amortization, Physician Inputs, Volume & Financial Inputs, Inputs & Assumptions, Valuation Assumptions. | G9: - Build the Volume & Financial Inputs tab as the historical TTM aggregator: create the FY/YTD/TTM column headers with the reporting date pulled from Inputs & Assumptions!E14, then pull each P&L line (Net Patient Revenue, Other Revenue, Supplies, SWB, Other Variable Direct/Indirect, Rent, Other Fixed, Bad Debt, Mgmt Fees, Depreciation, Interest, Other Expense/Income, UL and FL facility cash) from the corresponding TTM Dec17 and Apr18 TTM cells, and compute TTM = FY − YTD + partial-year, with EBITDA and Net Income subtotals plus OK/CHECK reconciliations against the sums. Add a Surgical Cases row linked from MD Summary Center and Physician Inputs, then a per-case metrics block dividing each cost/revenue line by cases for FY, partial-year, and TTM columns. - Build the Physician Inputs tab: (a) a KPIs & Volume by Physician block with monthly columns whose dates roll back from Inputs & Assumptions!E14 via EOMONTH, physician names pulled from MD Summary Center rows 6–79, monthly volumes pulled from MD Summary Center columns L–W, a TTM volume SUM across the 12 months, and a TTM Revenue column computed as NPR/Case × TTM volume; (b) a Total row using SUBTOTAL(109,...) and a per-IS tie-out to Volume & Financial Inputs!K37 and K11; (c) a KPIs & Volume by Specialty block using COUNTIF to count MDs and SUMIF to aggregate the monthly and TTM volumes/revenues by specialty, with a total row; (d) a Center Specific Seasonality block that MONTHs each column header, uses INDEX/MATCH against the Working Days Database to fetch working days per month, computes volume/day, then computes seasonality index vs. TTM average; (e) populate the month-date column B in the Working Days Database (rows 115–270) via EOMONTH stepping from a January-2014 seed while leaving the working-day counts already in column C intact. - On the Inputs & Assumptions tab, extend the CapEx schedule row (E95:I95) so year 1 pulls from Volume & Financial Inputs!K26 and each subsequent year references the prior year, and add the SUM total row (E97:I97); wire Modeled Year 1 Non-Compete and Mgmt Agmt amortization inputs to the Intangible Asset Amortization outputs (B22 and B20). - Build the Intangible Asset Amortization tab: pull Year 1 Revenue, EBIT (= EBITDA − Modeled Year 1 Dep), and Estimated Mgmt Fees from Pro Forma column CD; pull growth rate, discount rate, and tax rate from DCF & IRR; pull non-compete term from Inputs & Assumptions!E107 and Mgmt Expense per center from Inputs & Assumptions!G79. Add hardcodes: probability-adjusted impact of competition (increase from 15% to 25%), synergy discount rate override IF(B8=14%,20%,18%), and multipliers 0.85 and 1/3. Compute Management Agreement value as (($B$6*B12/3)*(1-$B$9))/(1+$D$8)*0.85 and Non-Compete value as ((($B$5*$B$11)*(1-$B$9))/($B$8-$B$7))*(1-((1+$B$7)/(1+$B$8))^$B$10)*(1+$D$8)*0.85; divide each by its life (from Inputs & Assumptions E110 and E107) to get amortization/year, then total and add an OK/CHECK against the D&A & Debt Schedules amortization row. - Build the D&A & Debt Schedules tab: (a) an assumptions block that pulls TTM Dep and Post-Close Dep from Inputs & Assumptions rows 102/103, non-compete and mgmt-agmt amortization amounts and lives from Inputs & Assumptions rows 106/107/109/110, and Facility Debt and Capital Lease terms from Inputs & Assumptions rows 114–119 and J114–J119, including a payment computed via −PMT(rate/12,months,principal,0) when terms = "Principal & Interest" and an "In Use?" flag = D29>0; (b) a monthly time header (H:CA) that references Pro Forma row 1/2/3/4; (c) monthly rows for CapEx (HLOOKUP against Inputs & Assumptions!$E$94:$I$97), Pre-Close and Post-Close Existing Depreciation, straight-line Depreciation on New Assets from the cumulative CapEx / period, Post-Close Amortization = non-compete/life/12 + mgmt-agmt/life/12, a fully-depreciated write-off via SUMIF against the CapEx history offset by the depreciation period, and Total D&A summing rows 8–12; (d) a Facility Debt amortization roll (Starting = prior Ending, Principal = MAX(Payment−Interest,0), Interest = rate/12 × Starting, Ending = Start−Principal); (e) a Capital Lease schedule with an escalating annual payment (=$D$34*POWER(1+$D$33,ceil(month/12)−1)) capped by starting balance, plus Straight-line Depreciation = Principal/Term. - Build the Pro Forma tab spine: header rows for month date (F4:BY4 via EOMONTH from Inputs & Assumptions!E14), year label (row 3 = YEAR), Post-Close period counter (row 2 = "Pre-Close" until the close date then E2+1), and year-of-close index (row 1 = ROUNDUP(period/12,0)). Add a right-side summary block: Avg TTM Month column (E), TTM totals column (CC) pulling from Volume & Financial Inputs, annual roll-up columns CD:CH using SUMIFS by row 1 year index, a CAGR column (CI) using POWER(CH/CC,1/5)−1, a Calendar Year block (CM:CT) linked directly to Volume & Financial Inputs plus CO = CN+1 propagation, and a Stub Periods block (CW:CY) built as TTM anchor from Volume & Financial Inputs!I column, YTD-to-Close as SUMIFS where row 2 = "Pre-Close" AND row 3 = YEAR(close), and Close-Dec as SUMIFS where row 3 = YEAR(close) AND row 2 > 0. - Build the Pro Forma Volume & Contribution Build section (rows 5–41): Base Cases from prior month × (1 + Organic Case Growth), Base Revenue/Supplies/SWB per Case each rolled from prior period × (1 + organic and inorganic growth pulled via SUMIFS against Inputs & Assumptions growth grids in rows 33–36 and 83–89); Decremental and Incremental cases/revenue/supplies/SWB via SUMIFS against Inputs & Assumptions rows 40–56 (matched on row 2 period); Total Cases/Revenue/Supplies/SWB summing base + inc + dec; Working Days adjustment via VLOOKUP into Physician Inputs Working Days Database controlled by an ON/OFF switch, Seasonality adjustment (SUMIF into Physician Inputs seasonality row) also switch-controlled, and Total Adjusted Cases = Total × (1+WD) × (1+Seasonality). - Build the Pro Forma monthly P&L (rows 43–58): Surgical Cases = adjusted cases, Surgical Revenue = cases × NPR/Case, Other Revenue = prior × (1 + Other Revenue growth from Inputs & Assumptions row 36), Supplies/SWB/Variable Direct = cases × per-case, Variable Indirect/Rent/Fixed = prior × (1 + growth from Inputs & Assumptions rows 83–89) with Rent zeroed when lease is Capital, Bad Debt = Revenue × Bad Debt %, RBO Fee = Inputs & Assumptions!E73 × (Revenue − Bad Debt) suppressed pre-close, Integration Expenses = Inputs & Assumptions!E76 for months ≤ E76 cutoff, EBITDAM = Revenue − sum(costs). - Build the Pro Forma Management Fee scenario block (rows 60–70): three scenario rows pulling scenario names from Inputs & Assumptions rows 69–71, monthly fee formulas per scenario (Scenario 1 = fee% × (Surgical Revenue − Bad Debt); Scenario 2 = MIN(Scenario 1, cap × POWER(1+esc, year−1) minus prior YTD); Scenario 3 = fixed × POWER(1+esc, year−1)/12), % of NPR-BD and Northstar % of Fee driven via CHOOSE from Inputs & Assumptions row 66, Active Scenario = CHOOSE(scenario#, S1, S2, S3), Northstar Mgmt Fee = Active × Northstar%, Other Mgmt Fee = Active × (1−Northstar%), EBITDA = EBITDAM − mgmt fees. - Build the Pro Forma below-the-line rows (72–91): Depreciation & Amortization, Interest Expense (facility + cap-lease) linked from D&A & Debt Schedules, Other Expense held flat from TTM, Net Income = EBITDA − D&A − Interest − Other, NOPAT = (NI × Northstar% + (Mgmt Fee + Overhead)) × (1−tax); KPI block for per-case metrics (rows 80–86); Northstar/MD/Other equity % rows driven by pre-close vs. post-close columns of Inputs & Assumptions rows 8–10; Bad Debt % of NPR; and a Growth block (rows 94–102) computing year-over-year change for each KPI plus SUMIF pulls of Other Revenue, Variable Direct/Indirect, Rent, and Fixed growth from Inputs & Assumptions. - Build the Pro Forma Unlevered Cash Flow section (rows 105–117): EBITDA link, LESS Rent if Cap Lease (from D&A schedule row 31), LESS CapEx via HLOOKUP into Inputs & Assumptions capex row/12, LESS ∆WC placeholder, UL Facility Cash sum; then Northstar layer: Northstar Distributions = UL Cash × Northstar%, LESS Northstar Taxes on Facility Earnings = MIN(−(NI+Interest) × Northstar% × tax, 0), ADD Northstar Mgmt Fee, LESS Northstar Overhead = Inputs & Assumptions!G79/12 post-close, LESS Northstar Taxes on Mgmt Fee = MIN(−(Fee+Overhead) × tax, 0), UL AT Northstar Cash. - Build the Pro Forma Facility Levered Cash Flow section (rows 119–137): EBITDA − Debt Principal (facility and cap lease from D&A schedule rows 21/29) − Interest (rows 22/30) − CapEx − ∆WC = Facility Levered Cash, then MD/Other Distributions = FL Cash × their %; Northstar block mirrors the UL layer except taxes exclude Interest addback (uses only Net Income) — FL AT Northstar Cash sum. - Build the Pro Forma IOI/E-NCI section (rows 139–173): switch on Inputs & Assumptions!$E$12 = "Consolidated" vs. Equity to select the reporting basis; Consolidated IOI = EBITDA + Mgmt Fee − D&A, Equity IOI = Net Income − Non-Controlling Income + Mgmt Fee, both zeroed when Northstar % = 0 and suppressed pre-close; parallel Consolidated E-NCI = EBITDAM − Other Mgmt Fee − NCI and Equity E-NCI = AT Northstar Cash − NCI + Mgmt Fee; Pre-Overhead and Post-Overhead lines that add/subtract the Northstar Overhead row. - On the Valuation Assumptions tab, populate Multiple on Existing Fees (F9/Volume & Financial Inputs!K22), the Unlevered valuation column H (TTM EBITDA from Volume & Financial Inputs!K23 × Seller Multiple = EV, minus zero for existing debt/leases, times Northstar Equity % from Inputs & Assumptions!K8, plus Mgmt Fee Buyout and Deal Costs = Northstar Cash Outlay; Pro Rata Debt Assumption = 0; Total Capital Outlay), and the Facility Levered column J with the same structure except Existing Facility Debt and Capital Leases pulled from Inputs & Assumptions!E114 and J114 and Pro Rata Debt Assumption = Northstar % × (Debt + Leases). - Build the DCF & IRR tab Unlevered DCF (rows 5–32): assumption block pulling Income Tax from Inputs & Assumptions!E92, hardcoded Working Capital % = 2.5%, close date pulled from Inputs & Assumptions!E13, Discount Rate = 10%, Perpetuity Growth = 3%. Time header pulled from Pro Forma calendar-year block CO–CT with a Pre-Close/Close/Proj. classifier. Northstar AT Unlevered Cash pulled from Pro Forma row 117 across CO:CT, LESS ∆WC × Northstar %, Terminal Value in the final column = Cash × (1+g)/(r−g), Year Fraction via YEARFRAC to year-end capped at 1, Discount Period stepping (Close = YF/2, subsequent = prior + 1 half-year), PV Factor = 1/(1+r)^period, PV of CF and PV of TV, sum to Enterprise Value (Northstar Portion), LESS Northstar Debt from Valuation Assumptions!J35, Equity Value. - Build the DCF & IRR Unlevered IRR ladder (rows 34–42): a purchase-price row anchored at close date whose columns walk out one half-year then annual thereafter (DATE(YEAR(prior)+1,6,30)), five discount tiers (Current = −(Northstar Equity + Mgmt Fee Buyout) from Valuation Assumptions H30+H31, plus ±5% and ±10% and an At-LOI copy), each column populated via SUMIFS of the AT Unlevered Cash rows keyed on year (else grown by the perpetuity growth rate), and XIRR against the date row; add a DCF check row that compares implied XIRR to the discount rate. - Build the DCF & IRR Levered DCF and Levered IRR (rows 44–72) mirroring the Unlevered structure but pulling Northstar AT Levered Cash from Pro Forma row 137 and pricing Current from Valuation Assumptions J30+J31. - Build the DCF & IRR DCF Sensitivity two-way data table (rows 74–92): row headers = perpetuity growth ±0.5% around K9 (rows 78), column headers = discount rate ±1% around K8 (col D), with an Enterprise Value block and an E-NCI Multiple block that divides EV by Pro Forma!$CQ$159 to convert to multiple. - Build the DCF & IRR ROIC block (rows 94–105): year headers walking forward from YEAR(K7), NOPAT row pulled from Pro Forma row 77 (with a perpetuity extension via prior × (1+g)), and a matrix that divides cumulative NOPAT by each purchase-price scenario (−D101…−D105) to yield ROIC per year per price scenario. | H9: a5f013b8-ef14-4437-bea0-630504093c40
