Workbook

Sheet Read me
B2: August 2026 AHT — prompt-only taskers
B3: Average handle time, the contributor list, and the whole method behind it
B5: THE ANSWER
B6: Median AHT — handle time (h) | C6: ='Checks'!C8 | F6: Paid time really spent on a finished task
B7: Mean AHT — handle time (h) | C7: ='Checks'!C7 | F7: Pulled up by a long right tail
B8: Median cost per task | C8: ='Checks'!C8*Assumptions!C10 | F8: At the blended rate
B9: Loaded hours per finished task | C9: =Assumptions!C9 | F9: All paid hours / tasks finished — use this to budget
B10: Loaded cost per finished task | C10: =Assumptions!C9*Assumptions!C10 | F10: What a finished task really costs
B12: SCOPE
B13: Project: sheets. Role: exactly prompt_tasker — nobody in this workbook holds a second role.
B14: Ali Mallick is excluded at the owner's request; their 4 tasks and 19.8 August hours are out of
B15: every figure here, including the calibration.
B16: Period: every task whose FIRST arrival in the audit state fell in August 2026, Eastern time.
B17: Population: 59 people — 48 credited with at least one such task, 11 who booked August hours
B18: but were never credited with one.
B19: A task in audit counts as done. That is the sheets convention, not a choice made here.
B21: WHAT'S IN EACH TAB
B22: Assumptions | C22: The three levers. Change one and every number in the workbook moves.
B23: AHT by contributor | C23: The 60-person list, sorted fastest to slowest on median AHT.
B24: Per-task detail | C24: All 905 tasks, one row each. This is the raw material everything else reads.
B25: Method and queries | C25: The six steps, each with the SQL that produced it.
B26: Checks | C26: The reconciliations that say the answer is sound, plus known weak points.
B28: HOW THE TIME IS MEASURED — IN PLAIN ENGLISH
B29: The platform stores no per-task timer, and payable time is recorded against the PROJECT, not
B30: against a task — there is no task id anywhere on the payable-time tables. So a task's time has to
B31: be reconstructed. Two records make that possible:
B33: the CLAIM — this person held this task from this moment to that one
B34: the PAYABLE SEGMENT — this person was clocked in and approved for pay over this window
B36: Intersect them. A paid minute falling inside a claim window on task X is a minute spent on task X.
B37: Sum those minutes across every claim the credited person ever had on the task, so a task that went
B38: out for review and came back for a redo picks up all of its rounds.
B40: Waiting is correctly excluded. Between rounds the task is not claimed and the person is not clocked
B41: in on it, so days sitting in review add nothing to AHT. That is elapsed cycle time — a different
B42: measure, and not what AHT is for.
... B65: Conventions from projects/sheets/project.md. Blue cells are inputs you may change; black cells are formulas.

Sheet Assumptions
B2: Assumptions and levers
B3: Yellow cells are the judgement calls. Change one and the whole workbook recalculates.
B5: Figure | C5: Value | E5: What it is
B6: Payable hours ON these tasks | C6: 801.7 | E6: Clocked, approved time that falls inside a claim window on one of the tasks that reached audit in August, for the person credited with it. This is what the AHT column adds up to.
B7: Cohort payable hours, August | C7: 1769.3 | E7: Everything these people were paid for in August, whatever they were working on. From payable_time_revision_segments allocated to the day the work happened.
B8: Share landing on these tasks | C8: =C6/C7 -> 0.45311705 | E8: The rest went to tasks that reached audit in another month or not at all, to tasks credited to someone else, to calibration and onboarding, and to clocked time with no task claimed.
B9: Loaded hours per finished task | C9: =C7/'Checks'!C6 -> 1.9615299 | E9: Cohort payable hours divided by tasks finished. THE COSTING NUMBER: somebody pays for the work that did not finish, so this is what a finished task really costs in time.
B10: Blended rate ($/hour) | C10: 163.33 | E10: Cohort August cost divided by cohort August hours. Used for pooled cost figures; each person's own rate is used in their own row.
B12: Two ways to read a task's time — both are here on purpose
B13: HANDLE TIME (the AHT column): paid time actually spent on that task. Answers "how long does the work take".
B14: LOADED TIME (the figure above): all paid time divided by tasks finished. Answers "what does a finished task cost".
B15: Handle time is the smaller number because it excludes work on tasks that never finished. Use handle time to
B16: compare people; use loaded time to budget.
B18: Where a paid second goes when someone holds several tasks at once
B19: A paid minute is matched to whichever task the person had claimed at that minute. If they had two tasks
B20: claimed, the minute is split between them in proportion to the overlap, so no minute is counted twice and
B21: the parts can never add up to more than they were paid. Someone who keeps many tasks open at once will
B22: therefore show a low AHT per task — that is arithmetic, not speed.

Sheet Per-task detail
A1: Task ID | B1: Contributor | C1: Email | D1: Payable hours on task | E1: Claim hours (capped 12h) | F1: Claims by contributor | G1: Cost at own rate ($) | H1: Rate ($/h)
A2: 4fb3c9ff-0b93-4811-89ff-79d2585ef82f | B2: Travis Crevasse | C2: travis.crevasse@gmail.com | D2: 0.1392 | E2: 12 | F2: 1 | G2: =D2*H2 -> 20.88 | H2: 150
A3: f4009a88-d44d-4679-ad7f-c383def3cb1c | B3: Charles Mack | C3: charliemack427@gmail.com | D3: 0.0183 | E3: 1.8628 | F3: 3 | G3: =D3*H3 -> 2.745 | H3: 150
A4: 62868a44-47a7-4851-ba02-fb09f713ba26 | B4: Charles Mack | C4: charliemack427@gmail.com | D4: 0.0198 | E4: 1.1639 | F4: 4 | G4: =D4*H4 -> 2.97 | H4: 150
A5: 3d153bf7-b66f-4d0c-bfb9-1420fc1b3c6f | B5: Charles Mack | C5: charliemack427@gmail.com | D5: 0.0214 | E5: 12.5104 | F5: 4 | G5: =D5*H5 -> 3.21 | H5: 150
A6: a9576bd9-db34-4d6e-bc84-7a47834e13a2 | B6: Charles Mack | C6: charliemack427@gmail.com | D6: 0.0248 | E6: 7.3604 | F6: 3 | G6: =D6*H6 -> 3.72 | H6: 150
A7: 9e11de46-03b3-4911-b00c-497aabb5e90b | B7: Charles Mack | C7: charliemack427@gmail.com | D7: 0.0289 | E7: 12.8573 | F7: 5 | G7: =D7*H7 -> 4.335 | H7: 150
A8: 86bde633-207f-4477-b658-fd86c706717f | B8: Charles Mack | C8: charliemack427@gmail.com | D8: 0.0341 | E8: 2.0623 | F8: 3 | G8: =D8*H8 -> 5.115 | H8: 150
A9: c600fbd7-b089-4296-95ab-4157989fd51c | B9: Charles Mack | C9: charliemack427@gmail.com | D9: 0.0343 | E9: 11.3398 | F9: 3 | G9: =D9*H9 -> 5.145 | H9: 150
A10: d0ec83fc-626e-48f8-8d82-8fce22363cc3 | B10: Charles Mack | C10: charliemack427@gmail.com | D10: 0.0693 | E10: 0.6301 | F10: 2 | G10: =D10*H10 -> 10.395 | H10: 150
A11: 1d62b031-e5ec-4bcc-8717-8cfb66d6607b | B11: Charles Mack | C11: charliemack427@gmail.com | D11: 0.0963 | E11: 15.9171 | F11: 5 | G11: =D11*H11 -> 14.445 | H11: 150
A12: 7ca41545-f90c-4a84-9c2c-7ac63cd975d2 | B12: Charles Mack | C12: charliemack427@gmail.com | D12: 0.0998 | E12: 12.6143 | F12: 4 | G12: =D12*H12 -> 14.97 | H12: 150
A13: bb34b33e-55a2-43bd-92b7-e70d4f6bb0f2 | B13: Charles Mack | C13: charliemack427@gmail.com | D13: 0.1159 | E13: 14.3098 | F13: 8 | G13: =D13*H13 -> 17.385 | H13: 150
... A510: 4df1da66-b648-41f1-b92f-95b0ff1b32b3 | B510: Johnny Tran | C510: jtran1123@gmail.com | D510: 0.5492 | E510: 13.1145 | F510: 4 | G510: =D510*H510 -> 82.38 | H510: 150
A511: 6330cda9-8153-4ebc-a0f9-2f00ccc30285 | B511: Johnny Tran | C511: jtran1123@gmail.com | D511: 0.6588 | G511: =D511*H511 | H511: 150
A512: 845b9c88-b682-4a76-af33-63df5ea95ba5 | B512: Johnny Tran | C512: jtran1123@gmail.com | D512: 0.7999 | E512: 20.6203 | F512: 4 | G512: =D512*H512 -> 119.985 | H512: 150
A513: 3f41d631-8fa7-4279-b19d-1b4ab89a59f1 | B513: Johnny Tran | C513: jtran1123@gmail.com | D513: 1.1195 | E513: 7.9506 | F513: 3 | G513: =D513*H513 -> 167.925 | H513: 150
A514: a0043af6-68da-4d6d-9867-cfff41005168 | B514: Johnny Tran | C514: jtran1123@gmail.com | D514: 1.2148 | E514: 24 | F514: 2 | G514: =D514*H514 -> 182.22 | H514: 150
A515: 35008ca3-b1e2-4c32-8358-d8baa2232eab | B515: Johnny Tran | C515: jtran1123@gmail.com | D515: 1.5088 | E515: 12.6693 | F515: 2 | G515: =D515*H515 -> 226.32 | H515: 150
A516: 712f5c60-dce4-444b-949f-e930814c93f4 | B516: Johnny Tran | C516: jtran1123@gmail.com | D516: 1.9891 | E516: 18.0597 | F516: 3 | G516: =D516*H516 -> 298.365 | H516: 150
A517: fe3b6f82-d540-45a7-b666-b6a803ce5931 | B517: Johnny Tran | C517: jtran1123@gmail.com | D517: 2.9107 | E517: 28.7754 | F517: 8 | G517: =D517*H517 -> 436.605 | H517: 150
A518: 9bdd3b09-5f56-42be-9254-be72e353faa6 | B518: Johnny Tran | C518: jtran1123@gmail.com | D518: 5.1805 | E518: 30.0881 | F518: 4 | G518: =D518*H518 -> 777.075 | H518: 150
A519: e28f77f9-4a5b-4d16-86ff-44c2b58df944 | B519: David Hua | C519: davidhua25@gmail.com | D519: 0.0108 | E519: 0.0257 | F519: 1 | G519: =D519*H519 -> 2.16 | H519: 200
A520: 135c6a37-e980-4faf-8c36-4e6b8490b76d | B520: David Hua | C520: davidhua25@gmail.com | D520: 0.0247 | E520: 2.3787 | F520: 1 | G520: =D520*H520 -> 4.94 | H520: 200
A521: 5c3d9dbd-1eec-44d8-9afc-55ba0c65d2ad | B521: David Hua | C521: davidhua25@gmail.com | D521: 0.0314 | E521: 2.5122 | F521: 2 | G521: =D521*H521 -> 6.28 | H521: 200
A522: 2413083f-71b8-442a-bf3a-1a0d469833d0 | B522: David Hua | C522: davidhua25@gmail.com | D522: 0.0345 | E522: 2.5757 | F522: 2 | G522: =D522*H522 -> 6.9 | H522: 200
A523: c0f3469c-a3da-4e9b-9510-ec40d2611ce5 | B523: David Hua | C523: davidhua25@gmail.com | D523: 0.054 | E523: 0.0773 | F523: 1 | G523: =D523*H523 -> 10.8 | H523: 200
... A903: e64b26fc-c112-4fa2-bb2e-f6508003fecc | B903: Winston Curteza | C903: wdc62@cornell.edu | D903: 8.6106 | E903: 68.8506 | F903: 6 | G903: =D903*H903 -> 1291.59 | H903: 150
A905: Blue = payable time measured against this task: clocked, approved minutes that fall inside one of this person's claim windows on it, summed across every time they held it, including across redo rounds. Grey = the raw claim window for reference, which is possession and includes idle time. 21 tasks show zero payable minutes: work done while the claim had lapsed, or paid before payable time was being recorded.

Sheet AHT by contributor
A2: AHT by contributor — fastest to slowest
A3: Prompt-only taskers, sheets, August 2026. Every statistic is a live formula over the Per-task detail tab.
A5: # | B5: Contributor | C5: Email | D5: AHT (h) | E5: Tasks | F5: Hours | G5: $/task
A6: 1 | B6: Travis Crevasse | C6: travis.crevasse@gmail.com | D6: =MEDIAN('Per-task detail'!$D$2:$D$2) -> 0.1392 | E6: =COUNT('Per-task detail'!$D$2:$D$2) -> 1 | F6: 5 | G6: =D6*'Per-task detail'!$H$2 -> 20.88
A7: 2 | B7: Charles Mack | C7: charliemack427@gmail.com | D7: =MEDIAN('Per-task detail'!$D$3:$D$29) -> 0.2227 | E7: =COUNT('Per-task detail'!$D$3:$D$29) -> 27 | F7: 55.66 | G7: =D7*'Per-task detail'!$H$3 -> 33.405
A8: 3 | B8: Melvan Hoo Jun Hong | C8: melvanhjh@gmail.com | D8: =MEDIAN('Per-task detail'!$D$30:$D$71) -> 0.24045 | E8: =COUNT('Per-task detail'!$D$30:$D$71) -> 42 | F8: 71.87 | G8: =D8*'Per-task detail'!$H$30 -> 48.09
A9: 4 | B9: Alema Louis | C9: alemalouis4@gmail.com | D9: =MEDIAN('Per-task detail'!$D$72:$D$73) -> 0.26575 | E9: =COUNT('Per-task detail'!$D$72:$D$73) -> 2 | F9: 8.02 | G9: =D9*'Per-task detail'!$H$72 -> 39.8625
A10: 5 | B10: Ran Meshulam | C10: ranchuk4@gmail.com | D10: =MEDIAN('Per-task detail'!$D$74:$D$104) -> 0.3036 | E10: =COUNT('Per-task detail'!$D$74:$D$104) -> 31 | F10: 76.17 | G10: =D10*'Per-task detail'!$H$74 -> 45.54
A11: 6 | B11: Andy Deng | C11: ajhdeng@gmail.com | D11: =MEDIAN('Per-task detail'!$D$105:$D$114) -> 0.3521 | E11: =COUNT('Per-task detail'!$D$105:$D$114) -> 10 | F11: 9.14 | G11: =D11*'Per-task detail'!$H$105 -> 52.815
A12: 7 | B12: Alex Moon | C12: alexmoon1212@gmail.com | D12: =MEDIAN('Per-task detail'!$D$115:$D$149) -> 0.3712 | E12: =COUNT('Per-task detail'!$D$115:$D$149) -> 35 | F12: 101.02 | G12: =D12*'Per-task detail'!$H$115 -> 55.68
A13: 8 | B13: Pravit Kochar | C13: pravitkochar@uchicago.edu | D13: =MEDIAN('Per-task detail'!$D$150:$D$165) -> 0.3774 | E13: =COUNT('Per-task detail'!$D$150:$D$165) -> 16 | F13: 26.75 | G13: =D13*'Per-task detail'!$H$150 -> 56.61
A14: 9 | B14: Ethan Ohana | C14: ethan.ohana214@gmail.com | D14: =MEDIAN('Per-task detail'!$D$166:$D$199) -> 0.3823 | E14: =COUNT('Per-task detail'!$D$166:$D$199) -> 34 | F14: 49.9 | G14: =D14*'Per-task detail'!$H$166 -> 57.345
A15: 10 | B15: Hinda Diakite | C15: diakite.hinda@gmail.com | D15: =MEDIAN('Per-task detail'!$D$200:$D$207) -> 0.38885 | E15: =COUNT('Per-task detail'!$D$200:$D$207) -> 8 | F15: 18.53 | G15: =D15*'Per-task detail'!$H$200 -> 58.3275
A16: 11 | B16: Sutton Zhang | C16: suttonzhang@hotmail.com | D16: =MEDIAN('Per-task detail'!$D$208:$D$302) -> 0.4432 | E16: =COUNT('Per-task detail'!$D$208:$D$302) -> 95 | F16: 88.14 | G16: =D16*'Per-task detail'!$H$208 -> 66.48
A17: 12 | B17: Frank Collier | C17: frankcollier2018@gmail.com | D17: =MEDIAN('Per-task detail'!$D$303:$D$360) -> 0.4682 | E17: =COUNT('Per-task detail'!$D$303:$D$360) -> 58 | F17: 84.31 | G17: =D17*'Per-task detail'!$H$303 -> 70.23
A18: 13 | B18: Spencer Dumas | C18: skdumas03@gmail.com | D18: =MEDIAN('Per-task detail'!$D$361:$D$386) -> 0.47125 | E18: =COUNT('Per-task detail'!$D$361:$D$386) -> 26 | F18: 20.76 | G18: =D18*'Per-task detail'!$H$361 -> 70.6875
A19: 14 | B19: Marc Levy | C19: marclevyp@gmail.com | D19: =MEDIAN('Per-task detail'!$D$387:$D$394) -> 0.47505 | E19: =COUNT('Per-task detail'!$D$387:$D$394) -> 8 | F19: 13.52 | G19: =D19*'Per-task detail'!$H$387 -> 71.2575
A20: 15 | B20: Elliot Saye | C20: esaye@umich.edu | D20: =MEDIAN('Per-task detail'!$D$395:$D$471) -> 0.4911 | E20: =COUNT('Per-task detail'!$D$395:$D$471) -> 77 | F20: 100.1 | G20: =D20*'Per-task detail'!$H$395 -> 98.22
A21: 16 | B21: Alex Fey | C21: alexdf06@gmail.com | D21: =MEDIAN('Per-task detail'!$D$472:$D$501) -> 0.5086 | E21: =COUNT('Per-task detail'!$D$472:$D$501) -> 30 | F21: 46.92 | G21: =D21*'Per-task detail'!$H$472 -> 101.72
A22: 17 | B22: Johnny Tran | C22: jtran1123@gmail.com | D22: =MEDIAN('Per-task detail'!$D$502:$D$518) -> 0.5492 | E22: =COUNT('Per-task detail'!$D$502:$D$518) -> 17 | F22: 66.64 | G22: =D22*'Per-task detail'!$H$502 -> 82.38
A23: 18 | B23: David Hua | C23: davidhua25@gmail.com | D23: =MEDIAN('Per-task detail'!$D$519:$D$560) -> 0.56475 | E23: =COUNT('Per-task detail'!$D$519:$D$560) -> 42 | F23: 40.18 | G23: =D23*'Per-task detail'!$H$519 -> 112.95
A24: 19 | B24: Siddhant Kumbhat | C24: sidkumbhat92@gmail.com | D24: =MEDIAN('Per-task detail'!$D$561:$D$604) -> 0.57495 | E24: =COUNT('Per-task detail'!$D$561:$D$604) -> 44 | F24: 72.26 | G24: =D24*'Per-task detail'!$H$561 -> 86.2425
A25: 20 | B25: Artus Granier | C25: artus.granier@live.fr | D25: =MEDIAN('Per-task detail'!$D$605:$D$630) -> 0.58925 | E25: =COUNT('Per-task detail'!$D$605:$D$630) -> 26 | F25: 38.19 | G25: =D25*'Per-task detail'!$H$605 -> 88.3875
A26: 21 | B26: Ariya Savla | C26: ariya.savla@gmail.com | D26: =MEDIAN('Per-task detail'!$D$631:$D$639) -> 0.6042 | E26: =COUNT('Per-task detail'!$D$631:$D$639) -> 9 | F26: 13.15 | G26: =D26*'Per-task detail'!$H$631 -> 90.63
A27: 22 | B27: John Wang | C27: johnlwang7@gmail.com | D27: =MEDIAN('Per-task detail'!$D$640:$D$707) -> 0.63515 | E27: =COUNT('Per-task detail'!$D$640:$D$707) -> 68 | F27: 110.14 | G27: =D27*'Per-task detail'!$H$640 -> 111.15125
A28: 23 | B28: Mitchell Kimball | C28: kimball.mitch@gmail.com | D28: =MEDIAN('Per-task detail'!$D$708:$D$708) -> 0.6796 | E28: =COUNT('Per-task detail'!$D$708:$D$708) -> 1 | F28: 2.94 | G28: =D28*'Per-task detail'!$H$708 -> 118.93
A29: 24 | B29: Caroline Rawe | C29: cmrawe@gmail.com | D29: =MEDIAN('Per-task detail'!$D$709:$D$711) -> 0.6977 | E29: =COUNT('Per-task detail'!$D$709:$D$711) -> 3 | F29: 3.22 | G29: =D29*'Per-task detail'!$H$709 -> 104.655
A30: 25 | B30: Liam Tuohy | C30: liamtuohy22@gmail.com | D30: =MEDIAN('Per-task detail'!$D$712:$D$736) -> 0.7041 | E30: =COUNT('Per-task detail'!$D$712:$D$736) -> 25 | F30: 41.55 | G30: =D30*'Per-task detail'!$H$712 -> 105.615
A31: 26 | B31: Joy Tokosi | C31: joyyomitokosi@gmail.com | D31: =MEDIAN('Per-task detail'!$D$737:$D$761) -> 0.7127 | E31: =COUNT('Per-task detail'!$D$737:$D$761) -> 25 | F31: 104.25 | G31: =D31*'Per-task detail'!$H$737 -> 106.905
A32: 27 | B32: Diego Inaki Pardo de Orellana | C32: diegopardo52300@gmail.com | D32: =MEDIAN('Per-task detail'!$D$762:$D$775) -> 0.7995 | E32: =COUNT('Per-task detail'!$D$762:$D$775) -> 14 | F32: 29.34 | G32: =D32*'Per-task detail'!$H$762 -> 139.9125
A33: 28 | B33: Tyler Collingbourne | C33: tcollingbourne@gmail.com | D33: =MEDIAN('Per-task detail'!$D$776:$D$792) -> 0.8177 | E33: =COUNT('Per-task detail'!$D$776:$D$792) -> 17 | F33: 33 | G33: =D33*'Per-task detail'!$H$776 -> 122.655
A34: 29 | B34: Shahwaiz Faisal | C34: sf554@cornell.edu | D34: =MEDIAN('Per-task detail'!$D$793:$D$795) -> 0.8196 | E34: =COUNT('Per-task detail'!$D$793:$D$795) -> 3 | F34: 6.83 | G34: =D34*'Per-task detail'!$H$793 -> 122.94
A35: 30 | B35: Jack Sorensen | C35: jackfsorensen@gmail.com | D35: =MEDIAN('Per-task detail'!$D$796:$D$798) -> 0.8285 | E35: =COUNT('Per-task detail'!$D$796:$D$798) -> 3 | F35: 5.05 | G35: =D35*'Per-task detail'!$H$796 -> 124.275
A36: 31 | B36: Daniel Zalevsky | C36: danz291517@gmail.com | D36: =MEDIAN('Per-task detail'!$D$799:$D$819) -> 0.8411 | E36: =COUNT('Per-task detail'!$D$799:$D$819) -> 21 | F36: 46.06 | G36: =D36*'Per-task detail'!$H$799 -> 126.165
A37: 32 | B37: Francisco Cerqueira | C37: cerqueirafda@gmail.com | D37: =MEDIAN('Per-task detail'!$D$820:$D$824) -> 0.8445 | E37: =COUNT('Per-task detail'!$D$820:$D$824) -> 5 | F37: 11.33 | G37: =D37*'Per-task detail'!$H$820 -> 147.7875
A38: 33 | B38: Alexander Koblansky | C38: alexkoblansky@gmail.com | D38: =MEDIAN('Per-task detail'!$D$825:$D$847) -> 0.8544 | E38: =COUNT('Per-task detail'!$D$825:$D$847) -> 23 | F38: 47.59 | G38: =D38*'Per-task detail'!$H$825 -> 128.16
A39: 34 | B39: Mia Chamoun | C39: miachamoun79@gmail.com | D39: =MEDIAN('Per-task detail'!$D$848:$D$849) -> 1.0069 | E39: =COUNT('Per-task detail'!$D$848:$D$849) -> 2 | F39: 2.18 | G39: =D39*'Per-task detail'!$H$848 -> 151.035
A40: 35 | B40: Will Briley | C40: wpbriley@gmail.com | D40: =MEDIAN('Per-task detail'!$D$850:$D$862) -> 1.0273 | E40: =COUNT('Per-task detail'!$D$850:$D$862) -> 13 | F40: 24.05 | G40: =D40*'Per-task detail'!$H$850 -> 154.095
A41: 36 | B41: Paul Dykes | C41: paul@insanityventures.com | D41: =MEDIAN('Per-task detail'!$D$863:$D$864) -> 1.04095 | E41: =COUNT('Per-task detail'!$D$863:$D$864) -> 2 | F41: 2.93 | G41: =D41*'Per-task detail'!$H$863 -> 156.1425
A42: 37 | B42: Mikel Pardo | C42: pardomikel11@gmail.com | D42: =MEDIAN('Per-task detail'!$D$865:$D$868) -> 1.11405 | E42: =COUNT('Per-task detail'!$D$865:$D$868) -> 4 | F42: 25.78 | G42: =D42*'Per-task detail'!$H$865 -> 167.1075
...

Sheet Method and queries
B2: Method — six steps, each with its query
B3: Everything below was run read-only against tsip_prd through the Metabase dataset API on 31 August 2026.
B5: STEP 1 — DEFINE THE POPULATION
B6: Who counts as a "prompt-only tasker"?
B7: The brief was to exclude anyone holding more than one role. Checking first: all 618 sheets members hold exactly one role row, so multiple roles do not occur in this data and nobody was excluded on that basis.
B8: Roles present: beginner_tasker 369, prompt_tasker 112, calibration_tasker 90, reviewer 19, decomp_prompt_tasker 10, calibration_failed 7, decomp_prompt_reviewer 3, decomp_tasker 3, beginner_tasker_reviewer 3, eval_hallucination_reviewer 2.
B9: JUDGEMENT CALL: the filter is role = 'prompt_tasker' exactly. That drops the hybrids and also people doing prompt work under a reviewer or beginner title — most consequentially the project's highest-volume contributor, who is beginner_tasker_reviewer. The role field is a permissions label, not a description of work.
B11: SELECT m.user_id::text, m.role::text AS role, m.stage::text AS stage, (u.deactivated_at IS NOT NULL) AS deactivated FROM tsip_project_members m JOIN tsip_users u ON u.id=m.user_id WHERE m.project_id='sheets'
B13: STEP 2 — DEFINE THE TASK SET
B14: Unique tasks that reached audit in August
B15: A task counts once, on its FIRST arrival in audit — min(created_at) where to_state = audit and the task was not already there. Without that, a task bounced back and re-audited would be counted twice.
B16: The month boundary is Eastern time. Database timestamps are naive UTC, so the conversion is a double convert: AT TIME ZONE 'UTC' AT TIME ZONE 'America/New_York'. Getting this wrong moves tasks between months at the edges.
... B53: -- Every strict prompt_tasker with August payable hours, and their August cost WITH internal AS ( SELECT id FROM tsip_users WHERE lower(split_part(email,'@',2)) IN ('meridian.ai','tsip.ai','op.workada.co','theworkapp.ai','thworkapp.ai', 'mail-tester.com','srv1.mail-tester.com','ia-tester.com')), pt AS (SELECT user_id FROM tsip_project_members WHERE project_id='sheets' AND role::text='prompt_tasker'), rev AS ( SELECT DISTINCT ON (ptr.payable_time_entry_id) ptr.id, ptr.total_seconds, ptr.started_at, pte.user_id FROM payable_time_revisions ptr JOIN payable_time_entries pte ON pte.id=ptr.payable_time_entry_id WHERE ptr.project_id='sheets' AND ptr.started_at >= '2026-07-28' ORDER BY ptr.payable_time_entry_id, ptr.revision_number DESC), seg AS ( SELECT (s.started_at AT TIME ZONE 'UTC' AT TIME ZONE 'America/New_York')::date AS day, r.user_id, s.total_seconds::numeric AS secs, r.started_at FROM rev r JOIN payable_time_revision_segments s ON s.revision_id=r.id WHERE r.user_id IN (SELECT user_id FROM pt) AND r.user_id NOT IN (SELECT id FROM internal)) SELECT seg.user_id::text, COALESCE(u.name,u.email) AS contributor, ROUND((sum(secs)/3600.0)::numeric,2) AS aug_payable_h, count(DISTINCT day) AS aug_active_days, ROUND((sum(secs/3600.0 * COALESCE(( SELECT cr.rate_cents_per_hour FROM contributor_rates cr WHERE cr.project_id='sheets' AND (cr.user_id=seg.user_id OR cr.user_id IS NULL) AND cr.effective_from<=seg.started_at AND (cr.effective_to IS NULL OR cr.effective_to>seg.started_at) ORDER BY (cr.user_id IS NOT NULL) DESC, cr.effective_from DESC LIMIT 1),0))/100.0)::numeric,2) AS aug_cost FROM seg JOIN tsip_users u ON u.id=seg.user_id WHERE day BETWEEN '2026-08-01' AND '2026-08-31' GROUP BY 1,2

Sheet Checks
B2: Checks and reconciliations
B3: Live values recomputed from this workbook, next to the figures they should equal.
B5: Check | C5: This workbook | D5: Expected | F5: What it tells you
B6: Tasks with claim data | C6: =COUNT('Per-task detail'!$D$2:$D$903) -> 902 | D6: 902 | F6: Every credited task with a claim record for the credited person. 903 were credited; 2 have no claim row.
B7: Mean AHT (hours) | C7: =AVERAGE('Per-task detail'!$D$2:$D$903) -> 0.88881596 | D7: 0.89 | F7: Pooled mean. Recomputes if you change the calibration factor.
B8: Median AHT (hours) | C8: =MEDIAN('Per-task detail'!$D$2:$D$903) -> 0.56325 | D8: 0.56 | F8: Pooled median — the figure to quote, because the mean is pulled up by a long right tail.
B9: Payable hours ON these tasks | C9: =SUM('Per-task detail'!$D$2:$D$903) -> 801.712 | D9: 801.7 | F9: Paid time attributed to the 904 finished tasks. Must be LESS than cohort payable hours — the gap is work on tasks that did not finish in August.
B10: Cohort August payable hours | C10: 1769.3 | D10: 1769.3 | F10: All paid hours for these 59 people in August, from payroll.
B11: Share landing on these tasks | C11: =C9/C10 -> 0.45311705 | D11: 0.453 | F11: Under 100% by construction. If this ever reads 100% the attribution is wrong.
B12: Contributors listed | C12: =COUNTA('AHT by contributor'!$B$6:$B$64) -> 59 | D12: 59 | F12: 48 credited with a task + 11 with August hours and no credited task.
B13: Cohort August cost ($) | C13: 288961 | D13: 288961 | F13: From payroll, independent of anything task-level. The cross-check query returned $291,936 for 59 people; less Ali Mallick's $2,974 that is $288,961 for 58.
B14: Implied blended rate ($/h) | C14: =C13/C10 -> 163.31939 | D14: 163.33 | F14: Cohort cost divided by cohort hours. Should land on the rate used for the pooled figures.
B16: Independent corroboration
B17: The payroll cross-check query (Method tab) re-derives the cohort's August hours and cost from payable_time_revision_segments and contributor_rates alone — it never touches tsip_tasks, tsip_state_transitions or tsip_task_claims. It returned 1,789.1 hours, 59 people, $291,936.
B18: That is the same 1,789.1 the calibration factor is built from, so the workbook's hours tie to money paid by two routes that share no table beyond the project id.
B20: What could still be wrong
B21: • AHT counts only paid time that fell inside a claim window. Work done after a claim lapsed is missed.
B22: • Only 45.3% of paid hours land on tasks that finished in August, so handle time is not a costing number — use loaded time for that.
B23: • Credit goes to the last submitter before audit. 92% of send-backs are self-fixed, so this is usually the same person — but not always.
B24: • The role filter excludes real prompt work done under reviewer or beginner titles, including the project's biggest producer. That is the requested scope, not an accident.
B25: • Everything is blended across task varieties. Patch-based still cannot be separated from greenfield in platform data.
B26: • Daurys gonell is credited with an August task but has no August payable time — the claim spans the month boundary. Immaterial at one task, but it shows the two data sources are not perfectly aligned.
B27: • Excluding Ali Mallick removes 4 tasks and 19.8 August hours from every figure here.
B28: • 21 of 904 tasks show zero payable minutes — work done while the claim had lapsed, or before payable time was recorded. They are kept at zero rather than dropped, which pulls the median down slightly.
B29: • A person holding several tasks at once has each paid minute split between them, so their AHT per task reads low. This is the biggest caveat on the ranking: it rewards claiming tightly, not working fast.
